Workbook

Sheet Página9
A1: IDdoInsumo | B1: Nome do Insumo | C1: Estoque de Segurança | D1: Total de Entradas | E1: Total de Saídas | F1: Estoque Real | G1: Status | H1: UN de Medida | I1: Valor Unit
A2: MCC046UC0164 | B2: APAGADOR P/ QUADRO BRANCO RADEX | C2: 1 | D2: =SUMIFS(E!D:D,E!B:B,A2) -> 2 | E2: =SUMIF(S!G:G,A2,S!D:D) -> 3 | F2: =D2-E2 -> -1 | G2: =IF(F2<=C2, "REPOR ESTOQUE", "OK") -> REPOR ESTOQUE | H2: UN
A3: MCC015UC0038 | B3: BOBINA SHRINK 500MM | C3: 3 | D3: =SUMIFS(E!D:D,E!B:B,A3) -> 54 | E3: =SUMIF(S!G:G,A3,S!D:D) -> 41 | F3: =D3-E3 -> 13 | G3: =IF(F3<=C3, "REPOR ESTOQUE", "OK") -> OK | H3: ROLO
A4: 30000107 | B4: CAIXA 7 | C4: 1000 | D4: =SUMIFS(E!D:D,E!B:B,A4) -> 0 | E4: =SUMIF(S!G:G,A4,S!D:D) -> 0 | F4: =D4-E4 -> 0 | G4: =IF(F4<=C4, "REPOR ESTOQUE", "OK") -> REPOR ESTOQUE | H4: UN
A5: 30000108 | B5: CAIXA 8 | C5: 1000 | D5: =SUMIFS(E!D:D,E!B:B,A5) -> 0 | E5: =SUMIF(S!G:G,A5,S!D:D) -> 0 | F5: =D5-E5 -> 0 | G5: =IF(F5<=C5, "REPOR ESTOQUE", "OK") -> REPOR ESTOQUE | H5: UN
A6: 30000109 | B6: CAIXA EMB PAPELÃO CV 295X255X70 | C6: 1000 | D6: =SUMIFS(E!D:D,E!B:B,A6) -> 0 | E6: =SUMIF(S!G:G,A6,S!D:D) -> 0 | F6: =D6-E6 -> 0 | G6: =IF(F6<=C6, "REPOR ESTOQUE", "OK") -> REPOR ESTOQUE | H6: UN
A7: 30000110 | B7: CAIXA EMB PAPELÃO CV 375X285X70 | C7: 1000 | D7: =SUMIFS(E!D:D,E!B:B,A7) -> 0 | E7: =SUMIF(S!G:G,A7,S!D:D) -> 0 | F7: =D7-E7 -> 0 | G7: =IF(F7<=C7, "REPOR ESTOQUE", "OK") -> REPOR ESTOQUE | H7: UN
A8: 30000101 | B8: CAIXA EMB PAPELÃO TF 285X215X280 | C8: 1000 | D8: =SUMIFS(E!D:D,E!B:B,A8) -> 0 | E8: =SUMIF(S!G:G,A8,S!D:D) -> 0 | F8: =D8-E8 -> 0 | G8: =IF(F8<=C8, "REPOR ESTOQUE", "OK") -> REPOR ESTOQUE | H8: UN
A9: 30000103 | B9: CAIXA EMB PAPELÃO TF 290X280X280 | C9: 1000 | D9: =SUMIFS(E!D:D,E!B:B,A9) -> 0 | E9: =SUMIF(S!G:G,A9,S!D:D) -> 0 | F9: =D9-E9 -> 0 | G9: =IF(F9<=C9, "REPOR ESTOQUE", "OK") -> REPOR ESTOQUE | H9: UN
A10: 30000104 | B10: CAIXA EMB PAPELÃO TF 345X290X280 | C10: 1000 | D10: =SUMIFS(E!D:D,E!B:B,A10) -> 0 | E10: =SUMIF(S!G:G,A10,S!D:D) -> 0 | F10: =D10-E10 -> 0 | G10: =IF(F10<=C10, "REPOR ESTOQUE", "OK") -> REPOR ESTOQUE | H10: UN
A11: 30000102 | B11: CAIXA EMB PAPELÃO TF 290X250X280 | C11: 1000 | D11: =SUMIFS(E!D:D,E!B:B,A11) -> 0 | E11: =SUMIF(S!G:G,A11,S!D:D) -> 0 | F11: =D11-E11 -> 0 | G11: =IF(F11<=C11, "REPOR ESTOQUE", "OK") -> REPOR ESTOQUE | H11: UN
A12: MCC046UC0210 | B12: CALCULADORA MESA 12 DIGITOS ZT 712 ZETA | C12: 1 | D12: =SUMIFS(E!D:D,E!B:B,A12) -> 20 | E12: =SUMIF(S!G:G,A12,S!D:D) -> 18 | F12: =D12-E12 -> 2 | G12: =IF(F12<=C12, "REPOR ESTOQUE", "OK") -> OK | H12: UN
A13: MCC046UC0215 | B13: CANETA ESFEROGRAFICA ECONOMIC AZUL BIC | C13: 15 | D13: =SUMIFS(E!D:D,E!B:B,A13) -> 168 | E13: =SUMIF(S!G:G,A13,S!D:D) -> 188 | F13: =D13-E13 -> -20 | G13: =IF(F13<=C13, "REPOR ESTOQUE", "OK") -> REPOR ESTOQUE | H13: UN
A14: MCC046UC0216 | B14: CANETA ESFEROGRAFICA ECONOMIC PRETA BIC | C14: 15 | D14: =SUMIFS(E!D:D,E!B:B,A14) -> 146 | E14: =SUMIF(S!G:G,A14,S!D:D) -> 57 | F14: =D14-E14 -> 89 | G14: =IF(F14<=C14, "REPOR ESTOQUE", "OK") -> OK | H14: UN
A15: MCC046UC0525 | B15: CANETA PINCEL ATOMICO AZUL PILOT 1100 | C15: 3 | D15: =SUMIFS(E!D:D,E!B:B,A15) -> 25 | E15: =SUMIF(S!G:G,A15,S!D:D) -> 20 | F15: =D15-E15 -> 5 | G15: =IF(F15<=C15, "REPOR ESTOQUE", "OK") -> OK | H15: UN
A16: MCC046UC0526 | B16: CANETA PINCEL ATOMICO PRETA PILOT 1100 | C16: 3 | D16: =SUMIFS(E!D:D,E!B:B,A16) -> 19 | E16: =SUMIF(S!G:G,A16,S!D:D) -> 18 | F16: =D16-E16 -> 1 | G16: =IF(F16<=C16, "REPOR ESTOQUE", "OK") -> REPOR ESTOQUE | H16: UN
A17: MCC046UC0674 | B17: CLIPS 6/0 | C17: 2 | D17: =SUMIFS(E!D:D,E!B:B,A17) -> 8 | E17: =SUMIF(S!G:G,A17,S!D:D) -> 0 | F17: =D17-E17 -> 8 | G17: =IF(F17<=C17, "REPOR ESTOQUE", "OK") -> OK | H17: CAIXA
A18: MCC046UC0052 | B18: CLIPS 8/0 | C18: 2 | D18: =SUMIFS(E!D:D,E!B:B,A18) -> 10 | E18: =SUMIF(S!G:G,A18,S!D:D) -> 0 | F18: =D18-E18 -> 10 | G18: =IF(F18<=C18, "REPOR ESTOQUE", "OK") -> OK | H18: CAIXA
A19: MCC046UC0617 | B19: CLIPS CHAPARRAU 2/0 CX C/100 UN GALV. | C19: 2 | D19: =SUMIFS(E!D:D,E!B:B,A19) -> 17 | E19: =SUMIF(S!G:G,A19,S!D:D) -> 1 | F19: =D19-E19 -> 16 | G19: =IF(F19<=C19, "REPOR ESTOQUE", "OK") -> OK | H19: UN
A20: MCC046UC0315 | B20: ESTILETE 18MM PLASTICO LARGO BRW | C20: 3 | D20: =SUMIFS(E!D:D,E!B:B,A20) -> 0 | E20: =SUMIF(S!G:G,A20,S!D:D) -> 0 | F20: =D20-E20 -> 0 | G20: =IF(F20<=C20, "REPOR ESTOQUE", "OK") -> REPOR ESTOQUE | H20: UN
A21: MCC046UC0660 | B21: ETIQUETA 70MM COORDENACAO | C21: 5 | D21: =SUMIFS(E!D:D,E!B:B,A21) -> 58 | E21: =SUMIF(S!G:G,A21,S!D:D) -> 23 | F21: =D21-E21 -> 35 | G21: =IF(F21<=C21, "REPOR ESTOQUE", "OK") -> OK | H21: ROLO
A22: MCC046UC0659 | B22: ETIQUETA 70MM PROFESSOR | C22: 5 | D22: =SUMIFS(E!D:D,E!B:B,A22) -> 59 | E22: =SUMIF(S!G:G,A22,S!D:D) -> 34 | F22: =D22-E22 -> 25 | G22: =IF(F22<=C22, "REPOR ESTOQUE", "OK") -> OK | H22: ROLO
A23: MCC046UC0599 | B23: ETIQUETA ADESIVA COUCHE AMARELA - 105X150MM SAS | C23: 5 | D23: =SUMIFS(E!D:D,E!B:B,A23) -> 101 | E23: =SUMIF(S!G:G,A23,S!D:D) -> 76 | F23: =D23-E23 -> 25 | G23: =IF(F23<=C23, "REPOR ESTOQUE", "OK") -> OK | H23: ROLO
... A26: MCC046UC0668 | B26: ETIQUETA ADESIVA COUCHE CINZA 100X150X1 | C26: 5 | D26: =SUMIFS(E!D:D,E!B:B,A26) -> 135 | E26: =SUMIF(S!G:G,A26,S!D:D) -> 31 | F26: =D26-E26 -> 104 | G26: =IF(F26<=C26, "REPOR ESTOQUE", "OK") -> OK | H26: ROLO
A27: MCC046UC0658 | B27: ETIQUETA ADESIVA COUCHE LARANJA 100X150X1 | C27: 5 | D27: =SUMIFS(E!D:D,E!B:B,A27) -> 60 | E27: =SUMIF(S!G:G,A27,S!D:D) -> 28 | F27: =D27-E27 -> 32 | G27: =IF(F27<=C27, "REPOR ESTOQUE", "OK") -> OK | H27: ROLO | I27: R$ 91,67
A28: MCC046UC0597 | B28: ETIQUETA ADESIVA COUCHE ROSA - SAS 105X150MM | C28: 5 | D28: =SUMIFS(E!D:D,E!B:B,A28) -> 100 | E28: =SUMIF(S!G:G,A28,S!D:D) -> 36 | F28: =D28-E28 -> 64 | G28: =IF(F28<=C28, "REPOR ESTOQUE", "OK") -> OK | H28: ROLO
A29: MCC049UC0516 | B29: ETIQUETA ADESIVA COUCHE VERDE CLARO - 105X150MM | C29: 5 | D29: =SUMIFS(E!D:D,E!B:B,A29) -> 83 | E29: =SUMIF(S!G:G,A29,S!D:D) -> 13 | F29: =D29-E29 -> 70 | G29: =IF(F29<=C29, "REPOR ESTOQUE", "OK") -> OK | H29: ROLO
A30: MCC015UC0047 | B30: ETIQUETA CORTESIA | C30: 5 | D30: =SUMIFS(E!D:D,E!B:B,A30) -> 27 | E30: =SUMIF(S!G:G,A30,S!D:D) -> 20 | F30: =D30-E30 -> 7 | G30: =IF(F30<=C30, "REPOR ESTOQUE", "OK") -> OK | H30: ROLO
A31: MCC046UC0687 | B31: ETIQUETA COUCHE - 100X100X 1 | C31: 20 | D31: =SUMIFS(E!D:D,E!B:B,A31) -> 484 | E31: =SUMIF(S!G:G,A31,S!D:D) -> 149 | F31: =D31-E31 -> 335 | G31: =IF(F31<=C31, "REPOR ESTOQUE", "OK") -> OK | H31: ROLO
A32: MCC046UC0695 | B32: ETIQUETA COUCHE 98X50X1 | C32: 20 | D32: =SUMIFS(E!D:D,E!B:B,A32) -> 620 | E32: =SUMIF(S!G:G,A32,S!D:D) -> 364 | F32: =D32-E32 -> 256 | G32: =IF(F32<=C32, "REPOR ESTOQUE", "OK") -> OK | H32: ROLO
A33: MCC046UC0679 | B33: EXTRATOR DE GRAMPO | C33: 3 | D33: =SUMIFS(E!D:D,E!B:B,A33) -> 16 | E33: =SUMIF(S!G:G,A33,S!D:D) -> 3 | F33: =D33-E33 -> 13 | G33: =IF(F33<=C33, "REPOR ESTOQUE", "OK") -> OK | H33: UN
A34: MCC015UC0008 | B34: FILME STRETCH 500X25 | C34: 40 | D34: =SUMIFS(E!D:D,E!B:B,A34) -> 1584 | E34: =SUMIF(S!G:G,A34,S!D:D) -> 1742 | F34: =D34-E34 -> -158 | G34: =IF(F34<=C34, "REPOR ESTOQUE", "OK") -> REPOR ESTOQUE | H34: ROLO
A35: MCC015UC0045 | B35: FITA ADESIVA 69MM X 100M | C35: 20 | D35: =SUMIFS(E!D:D,E!B:B,A35) -> 1927 | E35: =SUMIF(S!G:G,A35,S!D:D) -> 1640 | F35: =D35-E35 -> 287 | G35: =IF(F35<=C35, "REPOR ESTOQUE", "OK") -> OK | H35: UN
A36: MCC046UC0360 | B36: FITA ADESIVA DUPLA FACE 12mm X 20m 4910 VHB 3M | C36: 1 | D36: =SUMIFS(E!D:D,E!B:B,A36) -> 3 | E36: =SUMIF(S!G:G,A36,S!D:D) -> 127 | F36: =D36-E36 -> -124 | G36: =IF(F36<=C36, "REPOR ESTOQUE", "OK") -> REPOR ESTOQUE | H36: UN
A37: MCC049UC0600 | B37: FITA ADESIVA P/ CACHORRO PERSONALIZADA | C37: 10 | D37: =SUMIFS(E!D:D,E!B:B,A37) -> 424 | E37: =SUMIF(S!G:G,A37,S!D:D) -> 268 | F37: =D37-E37 -> 156 | G37: =IF(F37<=C37, "REPOR ESTOQUE", "OK") -> OK | H37: UN
A38: MCC015UC0033 | B38: FITA DE ARQUEAR PET VERDE 16MM X 0,8MM C/ 13KG | C38: 3 | D38: =SUMIFS(E!D:D,E!B:B,A38) -> 30 | E38: =SUMIF(S!G:G,A38,S!D:D) -> 26 | F38: =D38-E38 -> 4 | G38: =IF(F38<=C38, "REPOR ESTOQUE", "OK") -> OK | H38: UN
A39: MCC049UC0604 | B39: FITA DE DEMARCAÇÃO AMARELA | C39: 3 | D39: =SUMIFS(E!D:D,E!B:B,A39) -> 15 | E39: =SUMIF(S!G:G,A39,S!D:D) -> 27 | F39: =D39-E39 -> -12 | G39: =IF(F39<=C39, "REPOR ESTOQUE", "OK") -> REPOR ESTOQUE | H39: UN
... A70: MCC046UC0587 | B70: TESOURA USO GERAL 21CM MUNDIAL 160-8N | C70: 2 | D70: =SUMIFS(E!D:D,E!B:B,A70) -> 3 | E70: =SUMIF(S!G:G,A70,S!D:D) -> 4 | F70: =D70-E70 -> -1 | G70: =IF(F70<=C70, "REPOR ESTOQUE", "OK") -> REPOR ESTOQUE | H70: UN

Sheet Insumos
A1: CD | B1: CÓDIGO | C1: ITEM | D1: UNIDADE | E1: LEAD TIME | F1: ESTOQUE MÍNIMO | G1: ESTOQUE REAL | H1: STATUS | I1: CATEGORIA | J1: DIF
A2: FOR | B2: MCC015UC0038 | C2: BOBINA SHRINK 500MM | D2: BOBINA | E2: 2 | F2: 3 | G2: =SUMIF(Entradas!B:B, B2, Entradas!E:E) - SUMIF('Saídas'!C:C, B2, 'Saídas'!E:E) -> 10 | H2: =IF(G2<F2, "CRÍTICO", IF(G2<=F2, "ALERTA", "OK")) -> OK | I2: SHIRINK | J2: =G2-F2 -> 7
A3: FOR | B3: 30000107 | C3: CAIXA 7 | D3: UN | E3: 30 | F3: 3000 | G3: =SUMIF(Entradas!B:B, B3, Entradas!E:E) - SUMIF('Saídas'!C:C, B3, 'Saídas'!E:E) -> 9599 | H3: =IF(G3<F3, "CRÍTICO", IF(G3<=F3, "ALERTA", "OK")) -> OK | I3: CAIXA | J3: =G3-F3 -> 6599
A4: FOR | B4: 30000108 | C4: CAIXA 8 | D4: UN | E4: 30 | F4: 3000 | G4: =SUMIF(Entradas!B:B, B4, Entradas!E:E) - SUMIF('Saídas'!C:C, B4, 'Saídas'!E:E) -> 2500 | H4: =IF(G4<F4, "CRÍTICO", IF(G4<=F4, "ALERTA", "OK")) -> CRÍTICO | I4: CAIXA | J4: =G4-F4 -> -500
A5: FOR | B5: 30000109 | C5: CAIXA EMB PAPELÃO CV 295X255X70 | D5: UN | E5: 30 | F5: 3000 | G5: =SUMIF(Entradas!B:B, B5, Entradas!E:E) - SUMIF('Saídas'!C:C, B5, 'Saídas'!E:E) -> 1200 | H5: =IF(G5<F5, "CRÍTICO", IF(G5<=F5, "ALERTA", "OK")) -> CRÍTICO | I5: CAIXA | J5: =G5-F5 -> -1800
A6: FOR | B6: 30000110 | C6: CAIXA EMB PAPELÃO CV 375X285X70 | D6: UN | E6: 30 | F6: 3000 | G6: =SUMIF(Entradas!B:B, B6, Entradas!E:E) - SUMIF('Saídas'!C:C, B6, 'Saídas'!E:E) -> 45323 | H6: =IF(G6<F6, "CRÍTICO", IF(G6<=F6, "ALERTA", "OK")) -> OK | I6: CAIXA | J6: =G6-F6 -> 42323
A7: FOR | B7: 30000101 | C7: CAIXA EMB PAPELÃO TF 285X215X280 | D7: UN | E7: 30 | F7: 3000 | G7: =SUMIF(Entradas!B:B, B7, Entradas!E:E) - SUMIF('Saídas'!C:C, B7, 'Saídas'!E:E) -> 19500 | H7: =IF(G7<F7, "CRÍTICO", IF(G7<=F7, "ALERTA", "OK")) -> OK | I7: CAIXA | J7: =G7-F7 -> 16500
A8: FOR | B8: 30000103 | C8: CAIXA EMB PAPELÃO TF 290X280X280 | D8: UN | E8: 30 | F8: 3000 | G8: =SUMIF(Entradas!B:B, B8, Entradas!E:E) - SUMIF('Saídas'!C:C, B8, 'Saídas'!E:E) -> 18100 | H8: =IF(G8<F8, "CRÍTICO", IF(G8<=F8, "ALERTA", "OK")) -> OK | I8: CAIXA | J8: =G8-F8 -> 15100
A9: FOR | B9: 30000104 | C9: CAIXA EMB PAPELÃO TF 345X290X280 | D9: UN | E9: 30 | F9: 3000 | G9: =SUMIF(Entradas!B:B, B9, Entradas!E:E) - SUMIF('Saídas'!C:C, B9, 'Saídas'!E:E) -> 8000 | H9: =IF(G9<F9, "CRÍTICO", IF(G9<=F9, "ALERTA", "OK")) -> OK | I9: CAIXA | J9: =G9-F9 -> 5000
A10: FOR | B10: 30000102 | C10: CAIXA EMB PAPELÃO TF 290X250X280 | D10: UN | E10: 30 | F10: 3000 | G10: =SUMIF(Entradas!B:B, B10, Entradas!E:E) - SUMIF('Saídas'!C:C, B10, 'Saídas'!E:E) -> 16200 | H10: =IF(G10<F10, "CRÍTICO", IF(G10<=F10, "ALERTA", "OK")) -> OK | I10: CAIXA | J10: =G10-F10 -> 13200
A11: FOR | B11: MCC046C00003 | C11: ETIQUETA 70MM AVALIACAO | D11: ROLO | E11: 20 | F11: 5 | G11: =SUMIF(Entradas!B:B, B11, Entradas!E:E) - SUMIF('Saídas'!C:C, B11, 'Saídas'!E:E) -> 68 | H11: =IF(G11<F11, "CRÍTICO", IF(G11<=F11, "ALERTA", "OK")) -> OK | I11: ETIQUETA | J11: =G11-F11 -> 63
A12: FOR | B12: MCC046UC0660 | C12: ETIQUETA 70MM COORDENACAO | D12: ROLO | E12: 20 | F12: 10 | G12: =SUMIF(Entradas!B:B, B12, Entradas!E:E) - SUMIF('Saídas'!C:C, B12, 'Saídas'!E:E) -> 35 | H12: =IF(G12<F12, "CRÍTICO", IF(G12<=F12, "ALERTA", "OK")) -> OK | I12: ETIQUETA | J12: =G12-F12 -> 25
A13: FOR | B13: MCC046UC0659 | C13: ETIQUETA 70MM PROFESSOR | D13: ROLO | E13: 20 | F13: 10 | G13: =SUMIF(Entradas!B:B, B13, Entradas!E:E) - SUMIF('Saídas'!C:C, B13, 'Saídas'!E:E) -> 14 | H13: =IF(G13<F13, "CRÍTICO", IF(G13<=F13, "ALERTA", "OK")) -> OK | I13: ETIQUETA | J13: =G13-F13 -> 4
A14: FOR | B14: MCC046UC0599 | C14: ETIQUETA ADESIVA COUCHE AMARELA - 105X150MM SAS | D14: ROLO | E14: 20 | F14: 5 | G14: =SUMIF(Entradas!B:B, B14, Entradas!E:E) - SUMIF('Saídas'!C:C, B14, 'Saídas'!E:E) -> 2 | H14: =IF(G14<F14, "CRÍTICO", IF(G14<=F14, "ALERTA", "OK")) -> CRÍTICO | I14: ETIQUETA | J14: =G14-F14 -> -3
A15: FOR | B15: MCC046UC0598 | C15: ETIQUETA ADESIVA COUCHE AZUL - 105X150MM SAS | D15: ROLO | E15: 20 | F15: 10 | G15: =SUMIF(Entradas!B:B, B15, Entradas!E:E) - SUMIF('Saídas'!C:C, B15, 'Saídas'!E:E) -> 34 | H15: =IF(G15<F15, "CRÍTICO", IF(G15<=F15, "ALERTA", "OK")) -> OK | I15: ETIQUETA | J15: =G15-F15 -> 24
A16: FOR | B16: MCC046UC0596 | C16: ETIQUETA ADESIVA COUCHE BRANCA - 105X150MM SAS | D16: ROLO | E16: 3 | F16: 20 | G16: =SUMIF(Entradas!B:B, B16, Entradas!E:E) - SUMIF('Saídas'!C:C, B16, 'Saídas'!E:E) -> 480 | H16: =IF(G16<F16, "CRÍTICO", IF(G16<=F16, "ALERTA", "OK")) -> OK | I16: ETIQUETA | J16: =G16-F16 -> 460
A17: FOR | B17: MCC046UC0668 | C17: ETIQUETA ADESIVA COUCHE CINZA 100X150X1 | D17: ROLO | E17: 20 | F17: 10 | G17: =SUMIF(Entradas!B:B, B17, Entradas!E:E) - SUMIF('Saídas'!C:C, B17, 'Saídas'!E:E) -> 113 | H17: =IF(G17<F17, "CRÍTICO", IF(G17<=F17, "ALERTA", "OK")) -> OK | I17: ETIQUETA | J17: =G17-F17 -> 103
A18: FOR | B18: MCC046UC0658 | C18: ETIQUETA ADESIVA COUCHE LARANJA 100X150X1 | D18: ROLO | E18: 20 | F18: 10 | G18: =SUMIF(Entradas!B:B, B18, Entradas!E:E) - SUMIF('Saídas'!C:C, B18, 'Saídas'!E:E) -> 53 | H18: =IF(G18<F18, "CRÍTICO", IF(G18<=F18, "ALERTA", "OK")) -> OK | I18: ETIQUETA | J18: =G18-F18 -> 43
A19: FOR | B19: MCC046UC0597 | C19: ETIQUETA ADESIVA COUCHE ROSA - SAS 105X150MM | D19: ROLO | E19: 20 | F19: 10 | G19: =SUMIF(Entradas!B:B, B19, Entradas!E:E) - SUMIF('Saídas'!C:C, B19, 'Saídas'!E:E) -> 54 | H19: =IF(G19<F19, "CRÍTICO", IF(G19<=F19, "ALERTA", "OK")) -> OK | I19: ETIQUETA | J19: =G19-F19 -> 44
A20: FOR | B20: MCC049UC0516 | C20: ETIQUETA ADESIVA COUCHE VERDE CLARO - 105X150MM | D20: ROLO | E20: 20 | F20: 10 | G20: =SUMIF(Entradas!B:B, B20, Entradas!E:E) - SUMIF('Saídas'!C:C, B20, 'Saídas'!E:E) -> 62 | H20: =IF(G20<F20, "CRÍTICO", IF(G20<=F20, "ALERTA", "OK")) -> OK | I20: ETIQUETA | J20: =G20-F20 -> 52
A21: FOR | B21: MCC015UC0047 | C21: ETIQUETA CORTESIA | D21: ROLO | E21: 20 | F21: 20 | G21: =SUMIF(Entradas!B:B, B21, Entradas!E:E) - SUMIF('Saídas'!C:C, B21, 'Saídas'!E:E) -> 50 | H21: =IF(G21<F21, "CRÍTICO", IF(G21<=F21, "ALERTA", "OK")) -> OK | I21: ETIQUETA | J21: =G21-F21 -> 30
A22: FOR | B22: MCC046UC0687 | C22: ETIQUETA COUCHE - 100X100X 1 | D22: ROLO | E22: 3 | F22: 20 | G22: =SUMIF(Entradas!B:B, B22, Entradas!E:E) - SUMIF('Saídas'!C:C, B22, 'Saídas'!E:E) -> 127 | H22: =IF(G22<F22, "CRÍTICO", IF(G22<=F22, "ALERTA", "OK")) -> OK | I22: ETIQUETA | J22: =G22-F22 -> 107
... A39: FOR | B39: EMC015MO0007 | C39: RIBBON CERA PRETO 110MMX74M | D39: ROLO | E39: 3 | F39: 20 | G39: =SUMIF(Entradas!B:B, B39, Entradas!E:E) - SUMIF('Saídas'!C:C, B39, 'Saídas'!E:E) -> 669 | H39: =IF(G39<F39, "CRÍTICO", IF(G39<=F39, "ALERTA", "OK")) -> OK | I39: RIBBON | J39: =G39-F39 -> 649

Sheet PAINEL
A1: DATA | B1: CÓDIGO | C1: DESCRIÇÃO | D1: QUANT | E1: Movimentação | F1: RESPONSÁVEL | G1: ESTOQUE REAL | H1: ESTOQUE DE SEGURANÇA | I1: STATUS | J1: AJUSTADO | K1: SOLICITANTE
A2: =IFERROR(__xludf.DUMMYFUNCTION("VSTACK(filter(S!A2:A2002,S!A2:A2002<>""""),filter(E!A2:A2002,E!A2:A2002<>""""))"),45868.785046296296) -> 45868.785 | B2: =IFERROR(__xludf.DUMMYFUNCTION("VSTACK(filter(S!G2:G2002,S!G2:G2002<>""""),filter(E!B2:B2002,E!B2:B2002<>""""))"),"MCC015UC0045") -> MCC015UC0045 | C2: =IFERROR(__xludf.DUMMYFUNCTION("ARRAYFORMULA( REGEXREPLACE( VSTACK( FILTER(S!C2:C2002,S!C2:C2002<>""""), FILTER(E!C2:C2002,E!C2:C2002<>"""") ), ""^\S+\s+"", """" ) )"),"FITA ADESIVA 69MM X 100M") -> FITA ADESIVA 69MM X 100M | D2: =IFERROR(__xludf.DUMMYFUNCTION("VSTACK(filter(S!D2:D2002,S!D2:D2002<>""""),filter(E!D2:D2002,E!D2:D2002<>""""))"),10.0) -> 10 | E2: =IFERROR(__xludf.DUMMYFUNCTION("VSTACK(filter(S!H2:H2002,S!H2:H2002<>""""),filter(E!F2:F2002,E!F2:F2002<>""""))"),"Saída") -> Saída | F2: =IFERROR(__xludf.DUMMYFUNCTION("VSTACK(filter(S!E2:E2002,S!E2:E2002<>""""))"),"PMM:livro-voador:") -> PMM:livro-voador: | G2: {=XLOOKUP(B2,'Página9'!A:A,'Página9'!F:F,"")} -> 287 | H2: {=XLOOKUP(B2,'Página9'!A:A,'Página9'!C:C,"")} -> 20 | I2: {=XLOOKUP(B2,'Página9'!A:A,'Página9'!G:G,"")} -> OK | J2: =IF(F2=$N$2,"RECEBIMENTO",IF(F2=$N$3,"CIQ",IF(F2=$N$4,"PMM",IF(F2=$N$5,"ESTOQUE",IF(F2=$N$6,"EXPEDIÇÃO",""))))) -> PMM | K2: =IFERROR(__xludf.DUMMYFUNCTION("VSTACK(filter(S!I2:I2002,S!I2:I2002<>""""))"),"Jose Edervanio Lima Mateus") -> Jose Edervanio Lima Mateus | N2: Recebimento:truck:
A3: =IFERROR(__xludf.DUMMYFUNCTION("""COMPUTED_VALUE"""),45868.78525462963) -> 45868.785 | B3: =IFERROR(__xludf.DUMMYFUNCTION("""COMPUTED_VALUE"""),"MCC015UC0045") -> MCC015UC0045 | C3: =IFERROR(__xludf.DUMMYFUNCTION("""COMPUTED_VALUE"""),"FITA ADESIVA 69MM X 100M") -> FITA ADESIVA 69MM X 100M | D3: =IFERROR(__xludf.DUMMYFUNCTION("""COMPUTED_VALUE"""),4.0) -> 4 | E3: =IFERROR(__xludf.DUMMYFUNCTION("""COMPUTED_VALUE"""),"Saída") -> Saída | F3: =IFERROR(__xludf.DUMMYFUNCTION("""COMPUTED_VALUE"""),"Recebimento:truck:") -> Recebimento:truck: | G3: {=XLOOKUP(B3,'Página9'!A:A,'Página9'!F:F,"")} -> 287 | H3: {=XLOOKUP(B3,'Página9'!A:A,'Página9'!C:C,"")} -> 20 | I3: {=XLOOKUP(B3,'Página9'!A:A,'Página9'!G:G,"")} -> OK | J3: =IF(F3=$N$2,"RECEBIMENTO",IF(F3=$N$3,"CIQ",IF(F3=$N$4,"PMM",IF(F3=$N$5,"ESTOQUE",IF(F3=$N$6,"EXPEDIÇÃO",""))))) -> RECEBIMENTO | K3: =IFERROR(__xludf.DUMMYFUNCTION("""COMPUTED_VALUE"""),"Diego Araujo Dias") -> Diego Araujo Dias | N3: CIQ :qualidade:
A4: =IFERROR(__xludf.DUMMYFUNCTION("""COMPUTED_VALUE"""),45869.48354166667) -> 45869.484 | B4: =IFERROR(__xludf.DUMMYFUNCTION("""COMPUTED_VALUE"""),"MCC046UC0639") -> MCC046UC0639 | C4: =IFERROR(__xludf.DUMMYFUNCTION("""COMPUTED_VALUE"""),"PILHA ALCALINA ELGIN PEQ.AA ") -> PILHA ALCALINA ELGIN PEQ.AA | D4: =IFERROR(__xludf.DUMMYFUNCTION("""COMPUTED_VALUE"""),1.0) -> 1 | E4: =IFERROR(__xludf.DUMMYFUNCTION("""COMPUTED_VALUE"""),"Saída") -> Saída | F4: =IFERROR(__xludf.DUMMYFUNCTION("""COMPUTED_VALUE"""),"Recebimento:truck:") -> Recebimento:truck: | G4: {=XLOOKUP(B4,'Página9'!A:A,'Página9'!F:F,"")} -> -5 | H4: {=XLOOKUP(B4,'Página9'!A:A,'Página9'!C:C,"")} -> 4 | I4: {=XLOOKUP(B4,'Página9'!A:A,'Página9'!G:G,"")} -> REPOR ESTOQUE | J4: =IF(F4=$N$2,"RECEBIMENTO",IF(F4=$N$3,"CIQ",IF(F4=$N$4,"PMM",IF(F4=$N$5,"ESTOQUE",IF(F4=$N$6,"EXPEDIÇÃO",""))))) -> RECEBIMENTO | K4: =IFERROR(__xludf.DUMMYFUNCTION("""COMPUTED_VALUE"""),"Raimundo Reurison Belarmino Da Gama") -> Raimundo Reurison Belarmino Da Gama | N4: PMM:livro-voador:
A5: =IFERROR(__xludf.DUMMYFUNCTION("""COMPUTED_VALUE"""),45869.699421296296) -> 45869.699 | B5: =IFERROR(__xludf.DUMMYFUNCTION("""COMPUTED_VALUE"""),"MCC046UC0638") -> MCC046UC0638 | C5: =IFERROR(__xludf.DUMMYFUNCTION("""COMPUTED_VALUE"""),"PILHA ALCALINA ELGIN PALITO AAA ") -> PILHA ALCALINA ELGIN PALITO AAA | D5: =IFERROR(__xludf.DUMMYFUNCTION("""COMPUTED_VALUE"""),1.0) -> 1 | E5: =IFERROR(__xludf.DUMMYFUNCTION("""COMPUTED_VALUE"""),"Saída") -> Saída | F5: =IFERROR(__xludf.DUMMYFUNCTION("""COMPUTED_VALUE"""),"CIQ :qualidade:") -> CIQ :qualidade: | G5: {=XLOOKUP(B5,'Página9'!A:A,'Página9'!F:F,"")} -> 32 | H5: {=XLOOKUP(B5,'Página9'!A:A,'Página9'!C:C,"")} -> 4 | I5: {=XLOOKUP(B5,'Página9'!A:A,'Página9'!G:G,"")} -> OK | J5: =IF(F5=$N$2,"RECEBIMENTO",IF(F5=$N$3,"CIQ",IF(F5=$N$4,"PMM",IF(F5=$N$5,"ESTOQUE",IF(F5=$N$6,"EXPEDIÇÃO",""))))) -> CIQ | K5: =IFERROR(__xludf.DUMMYFUNCTION("""COMPUTED_VALUE"""),"Paulo Henrique Chagas De Oliveira") -> Paulo Henrique Chagas De Oliveira | N5: Estoque:package:
A6: =IFERROR(__xludf.DUMMYFUNCTION("""COMPUTED_VALUE"""),45873.0) -> 45873 | B6: =IFERROR(__xludf.DUMMYFUNCTION("""COMPUTED_VALUE"""),"MCC046UC0082") -> MCC046UC0082 | C6: =IFERROR(__xludf.DUMMYFUNCTION("""COMPUTED_VALUE"""),"PAPEL SULFITE A4 75G 500 FOLHAS") -> PAPEL SULFITE A4 75G 500 FOLHAS | D6: =IFERROR(__xludf.DUMMYFUNCTION("""COMPUTED_VALUE"""),2.0) -> 2 | E6: =IFERROR(__xludf.DUMMYFUNCTION("""COMPUTED_VALUE"""),"Saída") -> Saída | F6: =IFERROR(__xludf.DUMMYFUNCTION("""COMPUTED_VALUE"""),"PMM:livro-voador:") -> PMM:livro-voador: | G6: {=XLOOKUP(B6,'Página9'!A:A,'Página9'!F:F,"")} -> 163 | H6: {=XLOOKUP(B6,'Página9'!A:A,'Página9'!C:C,"")} -> 10 | I6: {=XLOOKUP(B6,'Página9'!A:A,'Página9'!G:G,"")} -> OK | J6: =IF(F6=$N$2,"RECEBIMENTO",IF(F6=$N$3,"CIQ",IF(F6=$N$4,"PMM",IF(F6=$N$5,"ESTOQUE",IF(F6=$N$6,"EXPEDIÇÃO",""))))) -> PMM | K6: =IFERROR(__xludf.DUMMYFUNCTION("""COMPUTED_VALUE"""),"Ana Virginia De Castro Costa") -> Ana Virginia De Castro Costa | N6: Expedição:ex-escolas-exponenciais:
A7: =IFERROR(__xludf.DUMMYFUNCTION("""COMPUTED_VALUE"""),45873.0) -> 45873 | B7: =IFERROR(__xludf.DUMMYFUNCTION("""COMPUTED_VALUE"""),"MCC046UC0398") -> MCC046UC0398 | C7: =IFERROR(__xludf.DUMMYFUNCTION("""COMPUTED_VALUE"""),"GRAMPO 26/6 COBREADO CX.C/5000 BACCHI") -> GRAMPO 26/6 COBREADO CX.C/5000 BACCHI | D7: =IFERROR(__xludf.DUMMYFUNCTION("""COMPUTED_VALUE"""),1.0) -> 1 | E7: =IFERROR(__xludf.DUMMYFUNCTION("""COMPUTED_VALUE"""),"Saída") -> Saída | F7: =IFERROR(__xludf.DUMMYFUNCTION("""COMPUTED_VALUE"""),"Recebimento:truck:") -> Recebimento:truck: | G7: {=XLOOKUP(B7,'Página9'!A:A,'Página9'!F:F,"")} -> -13 | H7: {=XLOOKUP(B7,'Página9'!A:A,'Página9'!C:C,"")} -> 3 | I7: {=XLOOKUP(B7,'Página9'!A:A,'Página9'!G:G,"")} -> REPOR ESTOQUE | J7: =IF(F7=$N$2,"RECEBIMENTO",IF(F7=$N$3,"CIQ",IF(F7=$N$4,"PMM",IF(F7=$N$5,"ESTOQUE",IF(F7=$N$6,"EXPEDIÇÃO",""))))) -> RECEBIMENTO | K7: =IFERROR(__xludf.DUMMYFUNCTION("""COMPUTED_VALUE"""),"Ana Virginia De Castro Costa") -> Ana Virginia De Castro Costa
A8: =IFERROR(__xludf.DUMMYFUNCTION("""COMPUTED_VALUE"""),45875.0) -> 45875 | B8: =IFERROR(__xludf.DUMMYFUNCTION("""COMPUTED_VALUE"""),"MCC049UC0600") -> MCC049UC0600 | C8: =IFERROR(__xludf.DUMMYFUNCTION("""COMPUTED_VALUE"""),"FITA ADESIVA P/ CACHORRO PERSONALIZADA") -> FITA ADESIVA P/ CACHORRO PERSONALIZADA | D8: =IFERROR(__xludf.DUMMYFUNCTION("""COMPUTED_VALUE"""),50.0) -> 50 | E8: =IFERROR(__xludf.DUMMYFUNCTION("""COMPUTED_VALUE"""),"Saída") -> Saída | F8: =IFERROR(__xludf.DUMMYFUNCTION("""COMPUTED_VALUE"""),"Recebimento:truck:") -> Recebimento:truck: | G8: {=XLOOKUP(B8,'Página9'!A:A,'Página9'!F:F,"")} -> 156 | H8: {=XLOOKUP(B8,'Página9'!A:A,'Página9'!C:C,"")} -> 10 | I8: {=XLOOKUP(B8,'Página9'!A:A,'Página9'!G:G,"")} -> OK | J8: =IF(F8=$N$2,"RECEBIMENTO",IF(F8=$N$3,"CIQ",IF(F8=$N$4,"PMM",IF(F8=$N$5,"ESTOQUE",IF(F8=$N$6,"EXPEDIÇÃO",""))))) -> RECEBIMENTO | K8: =IFERROR(__xludf.DUMMYFUNCTION("""COMPUTED_VALUE"""),"Francisco Antonio Pinheiro De Sousa") -> Francisco Antonio Pinheiro De Sousa
A9: =IFERROR(__xludf.DUMMYFUNCTION("""COMPUTED_VALUE"""),45875.0) -> 45875 | B9: =IFERROR(__xludf.DUMMYFUNCTION("""COMPUTED_VALUE"""),"MCC015UC0045") -> MCC015UC0045 | C9: =IFERROR(__xludf.DUMMYFUNCTION("""COMPUTED_VALUE"""),"FITA ADESIVA 69MM X 100M") -> FITA ADESIVA 69MM X 100M | D9: =IFERROR(__xludf.DUMMYFUNCTION("""COMPUTED_VALUE"""),24.0) -> 24 | E9: =IFERROR(__xludf.DUMMYFUNCTION("""COMPUTED_VALUE"""),"Saída") -> Saída | F9: =IFERROR(__xludf.DUMMYFUNCTION("""COMPUTED_VALUE"""),"Recebimento:truck:") -> Recebimento:truck: | G9: {=XLOOKUP(B9,'Página9'!A:A,'Página9'!F:F,"")} -> 287 | H9: {=XLOOKUP(B9,'Página9'!A:A,'Página9'!C:C,"")} -> 20 | I9: {=XLOOKUP(B9,'Página9'!A:A,'Página9'!G:G,"")} -> OK | J9: =IF(F9=$N$2,"RECEBIMENTO",IF(F9=$N$3,"CIQ",IF(F9=$N$4,"PMM",IF(F9=$N$5,"ESTOQUE",IF(F9=$N$6,"EXPEDIÇÃO",""))))) -> RECEBIMENTO | K9: =IFERROR(__xludf.DUMMYFUNCTION("""COMPUTED_VALUE"""),"Francisco Antonio Pinheiro De Sousa") -> Francisco Antonio Pinheiro De Sousa
A10: =IFERROR(__xludf.DUMMYFUNCTION("""COMPUTED_VALUE"""),45875.0) -> 45875 | B10: =IFERROR(__xludf.DUMMYFUNCTION("""COMPUTED_VALUE"""),"MCC046UC0596") -> MCC046UC0596 | C10: =IFERROR(__xludf.DUMMYFUNCTION("""COMPUTED_VALUE"""),"ETIQUETA ADESIVA COUCHE BRANCA - 105X150MM SAS") -> ETIQUETA ADESIVA COUCHE BRANCA - 105X150MM SAS | D10: =IFERROR(__xludf.DUMMYFUNCTION("""COMPUTED_VALUE"""),5.0) -> 5 | E10: =IFERROR(__xludf.DUMMYFUNCTION("""COMPUTED_VALUE"""),"Saída") -> Saída | F10: =IFERROR(__xludf.DUMMYFUNCTION("""COMPUTED_VALUE"""),"Recebimento:truck:") -> Recebimento:truck: | G10: {=XLOOKUP(B10,'Página9'!A:A,'Página9'!F:F,"")} -> 157 | H10: {=XLOOKUP(B10,'Página9'!A:A,'Página9'!C:C,"")} -> 20 | I10: {=XLOOKUP(B10,'Página9'!A:A,'Página9'!G:G,"")} -> OK | J10: =IF(F10=$N$2,"RECEBIMENTO",IF(F10=$N$3,"CIQ",IF(F10=$N$4,"PMM",IF(F10=$N$5,"ESTOQUE",IF(F10=$N$6,"EXPEDIÇÃO",""))))) -> RECEBIMENTO | K10: =IFERROR(__xludf.DUMMYFUNCTION("""COMPUTED_VALUE"""),"Francisco Antonio Pinheiro De Sousa") -> Francisco Antonio Pinheiro De Sousa
A11: =IFERROR(__xludf.DUMMYFUNCTION("""COMPUTED_VALUE"""),45875.0) -> 45875 | B11: =IFERROR(__xludf.DUMMYFUNCTION("""COMPUTED_VALUE"""),"MCC046UC0668") -> MCC046UC0668 | C11: =IFERROR(__xludf.DUMMYFUNCTION("""COMPUTED_VALUE"""),"ETIQUETA ADESIVA COUCHE CINZA 100X150X1") -> ETIQUETA ADESIVA COUCHE CINZA 100X150X1 | D11: =IFERROR(__xludf.DUMMYFUNCTION("""COMPUTED_VALUE"""),3.0) -> 3 | E11: =IFERROR(__xludf.DUMMYFUNCTION("""COMPUTED_VALUE"""),"Saída") -> Saída | F11: =IFERROR(__xludf.DUMMYFUNCTION("""COMPUTED_VALUE"""),"Estoque:package:") -> Estoque:package: | G11: {=XLOOKUP(B11,'Página9'!A:A,'Página9'!F:F,"")} -> 104 | H11: {=XLOOKUP(B11,'Página9'!A:A,'Página9'!C:C,"")} -> 5 | I11: {=XLOOKUP(B11,'Página9'!A:A,'Página9'!G:G,"")} -> OK | J11: =IF(F11=$N$2,"RECEBIMENTO",IF(F11=$N$3,"CIQ",IF(F11=$N$4,"PMM",IF(F11=$N$5,"ESTOQUE",IF(F11=$N$6,"EXPEDIÇÃO",""))))) -> ESTOQUE | K11: =IFERROR(__xludf.DUMMYFUNCTION("""COMPUTED_VALUE"""),"Francisco Antonio Pinheiro De Sousa") -> Francisco Antonio Pinheiro De Sousa
A12: =IFERROR(__xludf.DUMMYFUNCTION("""COMPUTED_VALUE"""),45875.0) -> 45875 | B12: =IFERROR(__xludf.DUMMYFUNCTION("""COMPUTED_VALUE"""),"MCC046UC0598") -> MCC046UC0598 | C12: =IFERROR(__xludf.DUMMYFUNCTION("""COMPUTED_VALUE"""),"ETIQUETA ADESIVA COUCHE AZUL - 105X150MM SAS") -> ETIQUETA ADESIVA COUCHE AZUL - 105X150MM SAS | D12: =IFERROR(__xludf.DUMMYFUNCTION("""COMPUTED_VALUE"""),3.0) -> 3 | E12: =IFERROR(__xludf.DUMMYFUNCTION("""COMPUTED_VALUE"""),"Saída") -> Saída | F12: =IFERROR(__xludf.DUMMYFUNCTION("""COMPUTED_VALUE"""),"Recebimento:truck:") -> Recebimento:truck: | G12: {=XLOOKUP(B12,'Página9'!A:A,'Página9'!F:F,"")} -> 40 | H12: {=XLOOKUP(B12,'Página9'!A:A,'Página9'!C:C,"")} -> 5 | I12: {=XLOOKUP(B12,'Página9'!A:A,'Página9'!G:G,"")} -> OK | J12: =IF(F12=$N$2,"RECEBIMENTO",IF(F12=$N$3,"CIQ",IF(F12=$N$4,"PMM",IF(F12=$N$5,"ESTOQUE",IF(F12=$N$6,"EXPEDIÇÃO",""))))) -> RECEBIMENTO | K12: =IFERROR(__xludf.DUMMYFUNCTION("""COMPUTED_VALUE"""),"Francisco Antonio Pinheiro De Sousa") -> Francisco Antonio Pinheiro De Sousa
A13: =IFERROR(__xludf.DUMMYFUNCTION("""COMPUTED_VALUE"""),45875.0) -> 45875 | B13: =IFERROR(__xludf.DUMMYFUNCTION("""COMPUTED_VALUE"""),"MCC046UC0597") -> MCC046UC0597 | C13: =IFERROR(__xludf.DUMMYFUNCTION("""COMPUTED_VALUE"""),"ETIQUETA ADESIVA COUCHE ROSA - SAS 105X150MM") -> ETIQUETA ADESIVA COUCHE ROSA - SAS 105X150MM | D13: =IFERROR(__xludf.DUMMYFUNCTION("""COMPUTED_VALUE"""),5.0) -> 5 | E13: =IFERROR(__xludf.DUMMYFUNCTION("""COMPUTED_VALUE"""),"Saída") -> Saída | F13: =IFERROR(__xludf.DUMMYFUNCTION("""COMPUTED_VALUE"""),"Estoque:package:") -> Estoque:package: | G13: {=XLOOKUP(B13,'Página9'!A:A,'Página9'!F:F,"")} -> 64 | H13: {=XLOOKUP(B13,'Página9'!A:A,'Página9'!C:C,"")} -> 5 | I13: {=XLOOKUP(B13,'Página9'!A:A,'Página9'!G:G,"")} -> OK | J13: =IF(F13=$N$2,"RECEBIMENTO",IF(F13=$N$3,"CIQ",IF(F13=$N$4,"PMM",IF(F13=$N$5,"ESTOQUE",IF(F13=$N$6,"EXPEDIÇÃO",""))))) -> ESTOQUE | K13: =IFERROR(__xludf.DUMMYFUNCTION("""COMPUTED_VALUE"""),"Francisco Antonio Pinheiro De Sousa") -> Francisco Antonio Pinheiro De Sousa
A14: =IFERROR(__xludf.DUMMYFUNCTION("""COMPUTED_VALUE"""),45875.0) -> 45875 | B14: =IFERROR(__xludf.DUMMYFUNCTION("""COMPUTED_VALUE"""),"MCC046UC0658") -> MCC046UC0658 | C14: =IFERROR(__xludf.DUMMYFUNCTION("""COMPUTED_VALUE"""),"ETIQUETA ADESIVA COUCHE LARANJA 100X150X1") -> ETIQUETA ADESIVA COUCHE LARANJA 100X150X1 | D14: =IFERROR(__xludf.DUMMYFUNCTION("""COMPUTED_VALUE"""),3.0) -> 3 | E14: =IFERROR(__xludf.DUMMYFUNCTION("""COMPUTED_VALUE"""),"Saída") -> Saída | F14: =IFERROR(__xludf.DUMMYFUNCTION("""COMPUTED_VALUE"""),"PMM:livro-voador:") -> PMM:livro-voador: | G14: {=XLOOKUP(B14,'Página9'!A:A,'Página9'!F:F,"")} -> 32 | H14: {=XLOOKUP(B14,'Página9'!A:A,'Página9'!C:C,"")} -> 5 | I14: {=XLOOKUP(B14,'Página9'!A:A,'Página9'!G:G,"")} -> OK | J14: =IF(F14=$N$2,"RECEBIMENTO",IF(F14=$N$3,"CIQ",IF(F14=$N$4,"PMM",IF(F14=$N$5,"ESTOQUE",IF(F14=$N$6,"EXPEDIÇÃO",""))))) -> PMM | K14: =IFERROR(__xludf.DUMMYFUNCTION("""COMPUTED_VALUE"""),"Francisco Antonio Pinheiro De Sousa") -> Francisco Antonio Pinheiro De Sousa
A15: =IFERROR(__xludf.DUMMYFUNCTION("""COMPUTED_VALUE"""),45875.0) -> 45875 | B15: =IFERROR(__xludf.DUMMYFUNCTION("""COMPUTED_VALUE"""),"MCC049UC0516") -> MCC049UC0516 | C15: =IFERROR(__xludf.DUMMYFUNCTION("""COMPUTED_VALUE"""),"ETIQUETA ADESIVA COUCHE VERDE CLARO - 105X150MM") -> ETIQUETA ADESIVA COUCHE VERDE CLARO - 105X150MM | D15: =IFERROR(__xludf.DUMMYFUNCTION("""COMPUTED_VALUE"""),2.0) -> 2 | E15: =IFERROR(__xludf.DUMMYFUNCTION("""COMPUTED_VALUE"""),"Saída") -> Saída | F15: =IFERROR(__xludf.DUMMYFUNCTION("""COMPUTED_VALUE"""),"CIQ :qualidade:") -> CIQ :qualidade: | G15: {=XLOOKUP(B15,'Página9'!A:A,'Página9'!F:F,"")} -> 70 | H15: {=XLOOKUP(B15,'Página9'!A:A,'Página9'!C:C,"")} -> 5 | I15: {=XLOOKUP(B15,'Página9'!A:A,'Página9'!G:G,"")} -> OK | J15: =IF(F15=$N$2,"RECEBIMENTO",IF(F15=$N$3,"CIQ",IF(F15=$N$4,"PMM",IF(F15=$N$5,"ESTOQUE",IF(F15=$N$6,"EXPEDIÇÃO",""))))) -> CIQ | K15: =IFERROR(__xludf.DUMMYFUNCTION("""COMPUTED_VALUE"""),"Francisco Antonio Pinheiro De Sousa") -> Francisco Antonio Pinheiro De Sousa
A16: =IFERROR(__xludf.DUMMYFUNCTION("""COMPUTED_VALUE"""),45875.0) -> 45875 | B16: =IFERROR(__xludf.DUMMYFUNCTION("""COMPUTED_VALUE"""),"MCC015UC0045") -> MCC015UC0045 | C16: =IFERROR(__xludf.DUMMYFUNCTION("""COMPUTED_VALUE"""),"FITA ADESIVA 69MM X 100M") -> FITA ADESIVA 69MM X 100M | D16: =IFERROR(__xludf.DUMMYFUNCTION("""COMPUTED_VALUE"""),10.0) -> 10 | E16: =IFERROR(__xludf.DUMMYFUNCTION("""COMPUTED_VALUE"""),"Saída") -> Saída | F16: =IFERROR(__xludf.DUMMYFUNCTION("""COMPUTED_VALUE"""),"PMM:livro-voador:") -> PMM:livro-voador: | G16: {=XLOOKUP(B16,'Página9'!A:A,'Página9'!F:F,"")} -> 287 | H16: {=XLOOKUP(B16,'Página9'!A:A,'Página9'!C:C,"")} -> 20 | I16: {=XLOOKUP(B16,'Página9'!A:A,'Página9'!G:G,"")} -> OK | J16: =IF(F16=$N$2,"RECEBIMENTO",IF(F16=$N$3,"CIQ",IF(F16=$N$4,"PMM",IF(F16=$N$5,"ESTOQUE",IF(F16=$N$6,"EXPEDIÇÃO",""))))) -> PMM | K16: =IFERROR(__xludf.DUMMYFUNCTION("""COMPUTED_VALUE"""),"Jose Antoniel Silva Mesquita") -> Jose Antoniel Silva Mesquita
A17: =IFERROR(__xludf.DUMMYFUNCTION("""COMPUTED_VALUE"""),45876.0) -> 45876 | B17: =IFERROR(__xludf.DUMMYFUNCTION("""COMPUTED_VALUE"""),"MCC046UC0659") -> MCC046UC0659 | C17: =IFERROR(__xludf.DUMMYFUNCTION("""COMPUTED_VALUE"""),"ETIQUETA 70MM PROFESSOR") -> ETIQUETA 70MM PROFESSOR | D17: =IFERROR(__xludf.DUMMYFUNCTION("""COMPUTED_VALUE"""),5.0) -> 5 | E17: =IFERROR(__xludf.DUMMYFUNCTION("""COMPUTED_VALUE"""),"Saída") -> Saída | F17: =IFERROR(__xludf.DUMMYFUNCTION("""COMPUTED_VALUE"""),"Recebimento:truck:") -> Recebimento:truck: | G17: {=XLOOKUP(B17,'Página9'!A:A,'Página9'!F:F,"")} -> 25 | H17: {=XLOOKUP(B17,'Página9'!A:A,'Página9'!C:C,"")} -> 5 | I17: {=XLOOKUP(B17,'Página9'!A:A,'Página9'!G:G,"")} -> OK | J17: =IF(F17=$N$2,"RECEBIMENTO",IF(F17=$N$3,"CIQ",IF(F17=$N$4,"PMM",IF(F17=$N$5,"ESTOQUE",IF(F17=$N$6,"EXPEDIÇÃO",""))))) -> RECEBIMENTO | K17: =IFERROR(__xludf.DUMMYFUNCTION("""COMPUTED_VALUE"""),"Philipe Araujo Barroso") -> Philipe Araujo Barroso
A18: =IFERROR(__xludf.DUMMYFUNCTION("""COMPUTED_VALUE"""),45876.0) -> 45876 | B18: =IFERROR(__xludf.DUMMYFUNCTION("""COMPUTED_VALUE"""),"MCC046UC0082") -> MCC046UC0082 | C18: =IFERROR(__xludf.DUMMYFUNCTION("""COMPUTED_VALUE"""),"PAPEL SULFITE A4 75G 500 FOLHAS") -> PAPEL SULFITE A4 75G 500 FOLHAS | D18: =IFERROR(__xludf.DUMMYFUNCTION("""COMPUTED_VALUE"""),1.0) -> 1 | E18: =IFERROR(__xludf.DUMMYFUNCTION("""COMPUTED_VALUE"""),"Saída") -> Saída | F18: =IFERROR(__xludf.DUMMYFUNCTION("""COMPUTED_VALUE"""),"Estoque:package:") -> Estoque:package: | G18: {=XLOOKUP(B18,'Página9'!A:A,'Página9'!F:F,"")} -> 163 | H18: {=XLOOKUP(B18,'Página9'!A:A,'Página9'!C:C,"")} -> 10 | I18: {=XLOOKUP(B18,'Página9'!A:A,'Página9'!G:G,"")} -> OK | J18: =IF(F18=$N$2,"RECEBIMENTO",IF(F18=$N$3,"CIQ",IF(F18=$N$4,"PMM",IF(F18=$N$5,"ESTOQUE",IF(F18=$N$6,"EXPEDIÇÃO",""))))) -> ESTOQUE | K18: =IFERROR(__xludf.DUMMYFUNCTION("""COMPUTED_VALUE"""),"Suellen Aguiar Da Silva") -> Suellen Aguiar Da Silva
A19: =IFERROR(__xludf.DUMMYFUNCTION("""COMPUTED_VALUE"""),45876.0) -> 45876 | B19: =IFERROR(__xludf.DUMMYFUNCTION("""COMPUTED_VALUE"""),"MCC046UC0687") -> MCC046UC0687 | C19: =IFERROR(__xludf.DUMMYFUNCTION("""COMPUTED_VALUE"""),"ETIQUETA COUCHE - 100X100X 1") -> ETIQUETA COUCHE - 100X100X 1 | D19: =IFERROR(__xludf.DUMMYFUNCTION("""COMPUTED_VALUE"""),1.0) -> 1 | E19: =IFERROR(__xludf.DUMMYFUNCTION("""COMPUTED_VALUE"""),"Saída") -> Saída | F19: =IFERROR(__xludf.DUMMYFUNCTION("""COMPUTED_VALUE"""),"Estoque:package:") -> Estoque:package: | G19: {=XLOOKUP(B19,'Página9'!A:A,'Página9'!F:F,"")} -> 335 | H19: {=XLOOKUP(B19,'Página9'!A:A,'Página9'!C:C,"")} -> 20 | I19: {=XLOOKUP(B19,'Página9'!A:A,'Página9'!G:G,"")} -> OK | J19: =IF(F19=$N$2,"RECEBIMENTO",IF(F19=$N$3,"CIQ",IF(F19=$N$4,"PMM",IF(F19=$N$5,"ESTOQUE",IF(F19=$N$6,"EXPEDIÇÃO",""))))) -> ESTOQUE | K19: =IFERROR(__xludf.DUMMYFUNCTION("""COMPUTED_VALUE"""),"Suellen Aguiar Da Silva") -> Suellen Aguiar Da Silva
A20: =IFERROR(__xludf.DUMMYFUNCTION("""COMPUTED_VALUE"""),45876.0) -> 45876 | B20: =IFERROR(__xludf.DUMMYFUNCTION("""COMPUTED_VALUE"""),"MCC015UC0008") -> MCC015UC0008 | C20: =IFERROR(__xludf.DUMMYFUNCTION("""COMPUTED_VALUE"""),"FILME STRETCH 500X25") -> FILME STRETCH 500X25 | D20: =IFERROR(__xludf.DUMMYFUNCTION("""COMPUTED_VALUE"""),3.0) -> 3 | E20: =IFERROR(__xludf.DUMMYFUNCTION("""COMPUTED_VALUE"""),"Saída") -> Saída | F20: =IFERROR(__xludf.DUMMYFUNCTION("""COMPUTED_VALUE"""),"Estoque:package:") -> Estoque:package: | G20: {=XLOOKUP(B20,'Página9'!A:A,'Página9'!F:F,"")} -> -158 | H20: {=XLOOKUP(B20,'Página9'!A:A,'Página9'!C:C,"")} -> 40 | I20: {=XLOOKUP(B20,'Página9'!A:A,'Página9'!G:G,"")} -> REPOR ESTOQUE | J20: =IF(F20=$N$2,"RECEBIMENTO",IF(F20=$N$3,"CIQ",IF(F20=$N$4,"PMM",IF(F20=$N$5,"ESTOQUE",IF(F20=$N$6,"EXPEDIÇÃO",""))))) -> ESTOQUE | K20: =IFERROR(__xludf.DUMMYFUNCTION("""COMPUTED_VALUE"""),"Francisco Samuel Trindade Nascimento") -> Francisco Samuel Trindade Nascimento
A21: =IFERROR(__xludf.DUMMYFUNCTION("""COMPUTED_VALUE"""),45877.0) -> 45877 | B21: =IFERROR(__xludf.DUMMYFUNCTION("""COMPUTED_VALUE"""),"MCC046UC0387") -> MCC046UC0387 | C21: =IFERROR(__xludf.DUMMYFUNCTION("""COMPUTED_VALUE"""),"GRAMPEADOR PLUS LINE CIS PRETO 26/6 P/20") -> GRAMPEADOR PLUS LINE CIS PRETO 26/6 P/20 | D21: =IFERROR(__xludf.DUMMYFUNCTION("""COMPUTED_VALUE"""),1.0) -> 1 | E21: =IFERROR(__xludf.DUMMYFUNCTION("""COMPUTED_VALUE"""),"Saída") -> Saída | F21: =IFERROR(__xludf.DUMMYFUNCTION("""COMPUTED_VALUE"""),"Estoque:package:") -> Estoque:package: | G21: {=XLOOKUP(B21,'Página9'!A:A,'Página9'!F:F,"")} -> 0 | H21: {=XLOOKUP(B21,'Página9'!A:A,'Página9'!C:C,"")} -> 1 | I21: {=XLOOKUP(B21,'Página9'!A:A,'Página9'!G:G,"")} -> REPOR ESTOQUE | J21: =IF(F21=$N$2,"RECEBIMENTO",IF(F21=$N$3,"CIQ",IF(F21=$N$4,"PMM",IF(F21=$N$5,"ESTOQUE",IF(F21=$N$6,"EXPEDIÇÃO",""))))) -> ESTOQUE | K21: =IFERROR(__xludf.DUMMYFUNCTION("""COMPUTED_VALUE"""),"Suellen Aguiar Da Silva") -> Suellen Aguiar Da Silva
A22: =IFERROR(__xludf.DUMMYFUNCTION("""COMPUTED_VALUE"""),45877.0) -> 45877 | B22: =IFERROR(__xludf.DUMMYFUNCTION("""COMPUTED_VALUE"""),"MCC046UC0526") -> MCC046UC0526 | C22: =IFERROR(__xludf.DUMMYFUNCTION("""COMPUTED_VALUE"""),"CANETA PINCEL ATOMICO PRETA PILOT 1100") -> CANETA PINCEL ATOMICO PRETA PILOT 1100 | D22: =IFERROR(__xludf.DUMMYFUNCTION("""COMPUTED_VALUE"""),1.0) -> 1 | E22: =IFERROR(__xludf.DUMMYFUNCTION("""COMPUTED_VALUE"""),"Saída") -> Saída | F22: =IFERROR(__xludf.DUMMYFUNCTION("""COMPUTED_VALUE"""),"Estoque:package:") -> Estoque:package: | G22: {=XLOOKUP(B22,'Página9'!A:A,'Página9'!F:F,"")} -> 1 | H22: {=XLOOKUP(B22,'Página9'!A:A,'Página9'!C:C,"")} -> 3 | I22: {=XLOOKUP(B22,'Página9'!A:A,'Página9'!G:G,"")} -> REPOR ESTOQUE | J22: =IF(F22=$N$2,"RECEBIMENTO",IF(F22=$N$3,"CIQ",IF(F22=$N$4,"PMM",IF(F22=$N$5,"ESTOQUE",IF(F22=$N$6,"EXPEDIÇÃO",""))))) -> ESTOQUE | K22: =IFERROR(__xludf.DUMMYFUNCTION("""COMPUTED_VALUE"""),"Diego Araujo Dias") -> Diego Araujo Dias
A23: =IFERROR(__xludf.DUMMYFUNCTION("""COMPUTED_VALUE"""),45877.0) -> 45877 | B23: =IFERROR(__xludf.DUMMYFUNCTION("""COMPUTED_VALUE"""),"MCC046UC0082") -> MCC046UC0082 | C23: =IFERROR(__xludf.DUMMYFUNCTION("""COMPUTED_VALUE"""),"PAPEL SULFITE A4 75G 500 FOLHAS") -> PAPEL SULFITE A4 75G 500 FOLHAS | D23: =IFERROR(__xludf.DUMMYFUNCTION("""COMPUTED_VALUE"""),1.0) -> 1 | E23: =IFERROR(__xludf.DUMMYFUNCTION("""COMPUTED_VALUE"""),"Saída") -> Saída | F23: =IFERROR(__xludf.DUMMYFUNCTION("""COMPUTED_VALUE"""),"PMM:livro-voador:") -> PMM:livro-voador: | G23: {=XLOOKUP(B23,'Página9'!A:A,'Página9'!F:F,"")} -> 163 | H23: {=XLOOKUP(B23,'Página9'!A:A,'Página9'!C:C,"")} -> 10 | I23: {=XLOOKUP(B23,'Página9'!A:A,'Página9'!G:G,"")} -> OK | J23: =IF(F23=$N$2,"RECEBIMENTO",IF(F23=$N$3,"CIQ",IF(F23=$N$4,"PMM",IF(F23=$N$5,"ESTOQUE",IF(F23=$N$6,"EXPEDIÇÃO",""))))) -> PMM | K23: =IFERROR(__xludf.DUMMYFUNCTION("""COMPUTED_VALUE"""),"Diego Araujo Dias") -> Diego Araujo Dias
A24: =IFERROR(__xludf.DUMMYFUNCTION("""COMPUTED_VALUE"""),45877.0) -> 45877 | B24: =IFERROR(__xludf.DUMMYFUNCTION("""COMPUTED_VALUE"""),"MCC046UC0599") -> MCC046UC0599 | C24: =IFERROR(__xludf.DUMMYFUNCTION("""COMPUTED_VALUE"""),"ETIQUETA ADESIVA COUCHE AMARELA - 105X150MM SAS") -> ETIQUETA ADESIVA COUCHE AMARELA - 105X150MM SAS | D24: =IFERROR(__xludf.DUMMYFUNCTION("""COMPUTED_VALUE"""),3.0) -> 3 | E24: =IFERROR(__xludf.DUMMYFUNCTION("""COMPUTED_VALUE"""),"Saída") -> Saída | F24: =IFERROR(__xludf.DUMMYFUNCTION("""COMPUTED_VALUE"""),"Recebimento:truck:") -> Recebimento:truck: | G24: {=XLOOKUP(B24,'Página9'!A:A,'Página9'!F:F,"")} -> 25 | H24: {=XLOOKUP(B24,'Página9'!A:A,'Página9'!C:C,"")} -> 5 | I24: {=XLOOKUP(B24,'Página9'!A:A,'Página9'!G:G,"")} -> OK | J24: =IF(F24=$N$2,"RECEBIMENTO",IF(F24=$N$3,"CIQ",IF(F24=$N$4,"PMM",IF(F24=$N$5,"ESTOQUE",IF(F24=$N$6,"EXPEDIÇÃO",""))))) -> RECEBIMENTO | K24: =IFERROR(__xludf.DUMMYFUNCTION("""COMPUTED_VALUE"""),"Philipe Araujo Barroso") -> Philipe Araujo Barroso
A25: =IFERROR(__xludf.DUMMYFUNCTION("""COMPUTED_VALUE"""),45877.0) -> 45877 | B25: =IFERROR(__xludf.DUMMYFUNCTION("""COMPUTED_VALUE"""),"MCC046UC0215") -> MCC046UC0215 | C25: =IFERROR(__xludf.DUMMYFUNCTION("""COMPUTED_VALUE"""),"CANETA ESFEROGRAFICA ECONOMIC AZUL BIC") -> CANETA ESFEROGRAFICA ECONOMIC AZUL BIC | D25: =IFERROR(__xludf.DUMMYFUNCTION("""COMPUTED_VALUE"""),15.0) -> 15 | E25: =IFERROR(__xludf.DUMMYFUNCTION("""COMPUTED_VALUE"""),"Saída") -> Saída | F25: =IFERROR(__xludf.DUMMYFUNCTION("""COMPUTED_VALUE"""),"Recebimento:truck:") -> Recebimento:truck: | G25: {=XLOOKUP(B25,'Página9'!A:A,'Página9'!F:F,"")} -> -20 | H25: {=XLOOKUP(B25,'Página9'!A:A,'Página9'!C:C,"")} -> 15 | I25: {=XLOOKUP(B25,'Página9'!A:A,'Página9'!G:G,"")} -> REPOR ESTOQUE | J25: =IF(F25=$N$2,"RECEBIMENTO",IF(F25=$N$3,"CIQ",IF(F25=$N$4,"PMM",IF(F25=$N$5,"ESTOQUE",IF(F25=$N$6,"EXPEDIÇÃO",""))))) -> RECEBIMENTO | K25: =IFERROR(__xludf.DUMMYFUNCTION("""COMPUTED_VALUE"""),"Jose Edervanio Lima Mateus") -> Jose Edervanio Lima Mateus
A26: =IFERROR(__xludf.DUMMYFUNCTION("""COMPUTED_VALUE"""),45880.0) -> 45880 | B26: =IFERROR(__xludf.DUMMYFUNCTION("""COMPUTED_VALUE"""),"MCC046UC0082") -> MCC046UC0082 | C26: =IFERROR(__xludf.DUMMYFUNCTION("""COMPUTED_VALUE"""),"PAPEL SULFITE A4 75G 500 FOLHAS") -> PAPEL SULFITE A4 75G 500 FOLHAS | D26: =IFERROR(__xludf.DUMMYFUNCTION("""COMPUTED_VALUE"""),10.0) -> 10 | E26: =IFERROR(__xludf.DUMMYFUNCTION("""COMPUTED_VALUE"""),"Saída") -> Saída | F26: =IFERROR(__xludf.DUMMYFUNCTION("""COMPUTED_VALUE"""),"Recebimento:truck:") -> Recebimento:truck: | G26: {=XLOOKUP(B26,'Página9'!A:A,'Página9'!F:F,"")} -> 163 | H26: {=XLOOKUP(B26,'Página9'!A:A,'Página9'!C:C,"")} -> 10 | I26: {=XLOOKUP(B26,'Página9'!A:A,'Página9'!G:G,"")} -> OK | J26: =IF(F26=$N$2,"RECEBIMENTO",IF(F26=$N$3,"CIQ",IF(F26=$N$4,"PMM",IF(F26=$N$5,"ESTOQUE",IF(F26=$N$6,"EXPEDIÇÃO",""))))) -> RECEBIMENTO | K26: =IFERROR(__xludf.DUMMYFUNCTION("""COMPUTED_VALUE"""),"Rubens Ribeiro Lisboa") -> Rubens Ribeiro Lisboa
A27: =IFERROR(__xludf.DUMMYFUNCTION("""COMPUTED_VALUE"""),45880.0) -> 45880 | B27: =IFERROR(__xludf.DUMMYFUNCTION("""COMPUTED_VALUE"""),"EMC015MO0001") -> EMC015MO0001 | C27: =IFERROR(__xludf.DUMMYFUNCTION("""COMPUTED_VALUE"""),"RIBBON CERA PRETO 110MMX300M") -> RIBBON CERA PRETO 110MMX300M | D27: =IFERROR(__xludf.DUMMYFUNCTION("""COMPUTED_VALUE"""),24.0) -> 24 | E27: =IFERROR(__xludf.DUMMYFUNCTION("""COMPUTED_VALUE"""),"Saída") -> Saída | F27: =IFERROR(__xludf.DUMMYFUNCTION("""COMPUTED_VALUE"""),"Recebimento:truck:") -> Recebimento:truck: | G27: {=XLOOKUP(B27,'Página9'!A:A,'Página9'!F:F,"")} -> 390 | H27: {=XLOOKUP(B27,'Página9'!A:A,'Página9'!C:C,"")} -> 5 | I27: {=XLOOKUP(B27,'Página9'!A:A,'Página9'!G:G,"")} -> OK | J27: =IF(F27=$N$2,"RECEBIMENTO",IF(F27=$N$3,"CIQ",IF(F27=$N$4,"PMM",IF(F27=$N$5,"ESTOQUE",IF(F27=$N$6,"EXPEDIÇÃO",""))))) -> RECEBIMENTO | K27: =IFERROR(__xludf.DUMMYFUNCTION("""COMPUTED_VALUE"""),"Rubens Ribeiro Lisboa") -> Rubens Ribeiro Lisboa
A28: =IFERROR(__xludf.DUMMYFUNCTION("""COMPUTED_VALUE"""),45880.0) -> 45880 | B28: =IFERROR(__xludf.DUMMYFUNCTION("""COMPUTED_VALUE"""),"MCC015UC0038") -> MCC015UC0038 | C28: =IFERROR(__xludf.DUMMYFUNCTION("""COMPUTED_VALUE"""),"BOBINA SHRINK 500MM") -> BOBINA SHRINK 500MM | D28: =IFERROR(__xludf.DUMMYFUNCTION("""COMPUTED_VALUE"""),1.0) -> 1 | E28: =IFERROR(__xludf.DUMMYFUNCTION("""COMPUTED_VALUE"""),"Saída") -> Saída | F28: =IFERROR(__xludf.DUMMYFUNCTION("""COMPUTED_VALUE"""),"Recebimento:truck:") -> Recebimento:truck: | G28: {=XLOOKUP(B28,'Página9'!A:A,'Página9'!F:F,"")} -> 13 | H28: {=XLOOKUP(B28,'Página9'!A:A,'Página9'!C:C,"")} -> 3 | I28: {=XLOOKUP(B28,'Página9'!A:A,'Página9'!G:G,"")} -> OK | J28: =IF(F28=$N$2,"RECEBIMENTO",IF(F28=$N$3,"CIQ",IF(F28=$N$4,"PMM",IF(F28=$N$5,"ESTOQUE",IF(F28=$N$6,"EXPEDIÇÃO",""))))) -> RECEBIMENTO | K28: =IFERROR(__xludf.DUMMYFUNCTION("""COMPUTED_VALUE"""),"Rubens Ribeiro Lisboa") -> Rubens Ribeiro Lisboa
A29: =IFERROR(__xludf.DUMMYFUNCTION("""COMPUTED_VALUE"""),45880.0) -> 45880 | B29: =IFERROR(__xludf.DUMMYFUNCTION("""COMPUTED_VALUE"""),"MCC046UC0215") -> MCC046UC0215 | C29: =IFERROR(__xludf.DUMMYFUNCTION("""COMPUTED_VALUE"""),"CANETA ESFEROGRAFICA ECONOMIC AZUL BIC") -> CANETA ESFEROGRAFICA ECONOMIC AZUL BIC | D29: =IFERROR(__xludf.DUMMYFUNCTION("""COMPUTED_VALUE"""),3.0) -> 3 | E29: =IFERROR(__xludf.DUMMYFUNCTION("""COMPUTED_VALUE"""),"Saída") -> Saída | F29: =IFERROR(__xludf.DUMMYFUNCTION("""COMPUTED_VALUE"""),"Recebimento:truck:") -> Recebimento:truck: | G29: {=XLOOKUP(B29,'Página9'!A:A,'Página9'!F:F,"")} -> -20 | H29: {=XLOOKUP(B29,'Página9'!A:A,'Página9'!C:C,"")} -> 15 | I29: {=XLOOKUP(B29,'Página9'!A:A,'Página9'!G:G,"")} -> REPOR ESTOQUE | J29: =IF(F29=$N$2,"RECEBIMENTO",IF(F29=$N$3,"CIQ",IF(F29=$N$4,"PMM",IF(F29=$N$5,"ESTOQUE",IF(F29=$N$6,"EXPEDIÇÃO",""))))) -> RECEBIMENTO | K29: =IFERROR(__xludf.DUMMYFUNCTION("""COMPUTED_VALUE"""),"Philipe Araujo Barroso") -> Philipe Araujo Barroso
A30: =IFERROR(__xludf.DUMMYFUNCTION("""COMPUTED_VALUE"""),45881.0) -> 45881 | B30: =IFERROR(__xludf.DUMMYFUNCTION("""COMPUTED_VALUE"""),"MCC015UC0045") -> MCC015UC0045 | C30: =IFERROR(__xludf.DUMMYFUNCTION("""COMPUTED_VALUE"""),"FITA ADESIVA 69MM X 100M") -> FITA ADESIVA 69MM X 100M | D30: =IFERROR(__xludf.DUMMYFUNCTION("""COMPUTED_VALUE"""),1.0) -> 1 | E30: =IFERROR(__xludf.DUMMYFUNCTION("""COMPUTED_VALUE"""),"Saída") -> Saída | F30: =IFERROR(__xludf.DUMMYFUNCTION("""COMPUTED_VALUE"""),"Recebimento:truck:") -> Recebimento:truck: | G30: {=XLOOKUP(B30,'Página9'!A:A,'Página9'!F:F,"")} -> 287 | H30: {=XLOOKUP(B30,'Página9'!A:A,'Página9'!C:C,"")} -> 20 | I30: {=XLOOKUP(B30,'Página9'!A:A,'Página9'!G:G,"")} -> OK | J30: =IF(F30=$N$2,"RECEBIMENTO",IF(F30=$N$3,"CIQ",IF(F30=$N$4,"PMM",IF(F30=$N$5,"ESTOQUE",IF(F30=$N$6,"EXPEDIÇÃO",""))))) -> RECEBIMENTO | K30: =IFERROR(__xludf.DUMMYFUNCTION("""COMPUTED_VALUE"""),"Paulo Henrique Chagas De Oliveira") -> Paulo Henrique Chagas De Oliveira
A31: =IFERROR(__xludf.DUMMYFUNCTION("""COMPUTED_VALUE"""),45881.0) -> 45881 | B31: =IFERROR(__xludf.DUMMYFUNCTION("""COMPUTED_VALUE"""),"MCC046UC0687") -> MCC046UC0687 | C31: =IFERROR(__xludf.DUMMYFUNCTION("""COMPUTED_VALUE"""),"ETIQUETA COUCHE - 100X100X 1") -> ETIQUETA COUCHE - 100X100X 1 | D31: =IFERROR(__xludf.DUMMYFUNCTION("""COMPUTED_VALUE"""),3.0) -> 3 | E31: =IFERROR(__xludf.DUMMYFUNCTION("""COMPUTED_VALUE"""),"Saída") -> Saída | F31: =IFERROR(__xludf.DUMMYFUNCTION("""COMPUTED_VALUE"""),"Recebimento:truck:") -> Recebimento:truck: | G31: {=XLOOKUP(B31,'Página9'!A:A,'Página9'!F:F,"")} -> 335 | H31: {=XLOOKUP(B31,'Página9'!A:A,'Página9'!C:C,"")} -> 20 | I31: {=XLOOKUP(B31,'Página9'!A:A,'Página9'!G:G,"")} -> OK | J31: =IF(F31=$N$2,"RECEBIMENTO",IF(F31=$N$3,"CIQ",IF(F31=$N$4,"PMM",IF(F31=$N$5,"ESTOQUE",IF(F31=$N$6,"EXPEDIÇÃO",""))))) -> RECEBIMENTO | K31: =IFERROR(__xludf.DUMMYFUNCTION("""COMPUTED_VALUE"""),"Paulo Henrique Chagas De Oliveira") -> Paulo Henrique Chagas De Oliveira
A32: =IFERROR(__xludf.DUMMYFUNCTION("""COMPUTED_VALUE"""),45881.0) -> 45881 | B32: =IFERROR(__xludf.DUMMYFUNCTION("""COMPUTED_VALUE"""),"MCC015UC0008") -> MCC015UC0008 | C32: =IFERROR(__xludf.DUMMYFUNCTION("""COMPUTED_VALUE"""),"FILME STRETCH 500X25") -> FILME STRETCH 500X25 | D32: =IFERROR(__xludf.DUMMYFUNCTION("""COMPUTED_VALUE"""),3.0) -> 3 | E32: =IFERROR(__xludf.DUMMYFUNCTION("""COMPUTED_VALUE"""),"Saída") -> Saída | F32: =IFERROR(__xludf.DUMMYFUNCTION("""COMPUTED_VALUE"""),"CIQ :qualidade:") -> CIQ :qualidade: | G32: {=XLOOKUP(B32,'Página9'!A:A,'Página9'!F:F,"")} -> -158 | H32: {=XLOOKUP(B32,'Página9'!A:A,'Página9'!C:C,"")} -> 40 | I32: {=XLOOKUP(B32,'Página9'!A:A,'Página9'!G:G,"")} -> REPOR ESTOQUE | J32: =IF(F32=$N$2,"RECEBIMENTO",IF(F32=$N$3,"CIQ",IF(F32=$N$4,"PMM",IF(F32=$N$5,"ESTOQUE",IF(F32=$N$6,"EXPEDIÇÃO",""))))) -> CIQ | K32: =IFERROR(__xludf.DUMMYFUNCTION("""COMPUTED_VALUE"""),"Francisco Samuel Trindade Nascimento") -> Francisco Samuel Trindade Nascimento
A33: =IFERROR(__xludf.DUMMYFUNCTION("""COMPUTED_VALUE"""),45881.0) -> 45881 | B33: =IFERROR(__xludf.DUMMYFUNCTION("""COMPUTED_VALUE"""),"MCC015UC0045") -> MCC015UC0045 | C33: =IFERROR(__xludf.DUMMYFUNCTION("""COMPUTED_VALUE"""),"FITA ADESIVA 69MM X 100M") -> FITA ADESIVA 69MM X 100M | D33: =IFERROR(__xludf.DUMMYFUNCTION("""COMPUTED_VALUE"""),24.0) -> 24 | E33: =IFERROR(__xludf.DUMMYFUNCTION("""COMPUTED_VALUE"""),"Saída") -> Saída | F33: =IFERROR(__xludf.DUMMYFUNCTION("""COMPUTED_VALUE"""),"CIQ :qualidade:") -> CIQ :qualidade: | G33: {=XLOOKUP(B33,'Página9'!A:A,'Página9'!F:F,"")} -> 287 | H33: {=XLOOKUP(B33,'Página9'!A:A,'Página9'!C:C,"")} -> 20 | I33: {=XLOOKUP(B33,'Página9'!A:A,'Página9'!G:G,"")} -> OK | J33: =IF(F33=$N$2,"RECEBIMENTO",IF(F33=$N$3,"CIQ",IF(F33=$N$4,"PMM",IF(F33=$N$5,"ESTOQUE",IF(F33=$N$6,"EXPEDIÇÃO",""))))) -> CIQ | K33: =IFERROR(__xludf.DUMMYFUNCTION("""COMPUTED_VALUE"""),"Francisco Antonio Pinheiro De Sousa") -> Francisco Antonio Pinheiro De Sousa
A34: =IFERROR(__xludf.DUMMYFUNCTION("""COMPUTED_VALUE"""),45881.0) -> 45881 | B34: =IFERROR(__xludf.DUMMYFUNCTION("""COMPUTED_VALUE"""),"MCC046UC0216") -> MCC046UC0216 | C34: =IFERROR(__xludf.DUMMYFUNCTION("""COMPUTED_VALUE"""),"CANETA ESFEROGRAFICA ECONOMIC PRETA BIC") -> CANETA ESFEROGRAFICA ECONOMIC PRETA BIC | D34: =IFERROR(__xludf.DUMMYFUNCTION("""COMPUTED_VALUE"""),2.0) -> 2 | E34: =IFERROR(__xludf.DUMMYFUNCTION("""COMPUTED_VALUE"""),"Saída") -> Saída | F34: =IFERROR(__xludf.DUMMYFUNCTION("""COMPUTED_VALUE"""),"CIQ :qualidade:") -> CIQ :qualidade: | G34: {=XLOOKUP(B34,'Página9'!A:A,'Página9'!F:F,"")} -> 89 | H34: {=XLOOKUP(B34,'Página9'!A:A,'Página9'!C:C,"")} -> 15 | I34: {=XLOOKUP(B34,'Página9'!A:A,'Página9'!G:G,"")} -> OK | J34: =IF(F34=$N$2,"RECEBIMENTO",IF(F34=$N$3,"CIQ",IF(F34=$N$4,"PMM",IF(F34=$N$5,"ESTOQUE",IF(F34=$N$6,"EXPEDIÇÃO",""))))) -> CIQ | K34: =IFERROR(__xludf.DUMMYFUNCTION("""COMPUTED_VALUE"""),"Matheus De Almeida Rodrigues") -> Matheus De Almeida Rodrigues
A35: =IFERROR(__xludf.DUMMYFUNCTION("""COMPUTED_VALUE"""),45881.0) -> 45881 | B35: =IFERROR(__xludf.DUMMYFUNCTION("""COMPUTED_VALUE"""),"MCC046UC0398") -> MCC046UC0398 | C35: =IFERROR(__xludf.DUMMYFUNCTION("""COMPUTED_VALUE"""),"GRAMPO 26/6 COBREADO CX.C/5000 BACCHI") -> GRAMPO 26/6 COBREADO CX.C/5000 BACCHI | D35: =IFERROR(__xludf.DUMMYFUNCTION("""COMPUTED_VALUE"""),1.0) -> 1 | E35: =IFERROR(__xludf.DUMMYFUNCTION("""COMPUTED_VALUE"""),"Saída") -> Saída | F35: =IFERROR(__xludf.DUMMYFUNCTION("""COMPUTED_VALUE"""),"Estoque:package:") -> Estoque:package: | G35: {=XLOOKUP(B35,'Página9'!A:A,'Página9'!F:F,"")} -> -13 | H35: {=XLOOKUP(B35,'Página9'!A:A,'Página9'!C:C,"")} -> 3 | I35: {=XLOOKUP(B35,'Página9'!A:A,'Página9'!G:G,"")} -> REPOR ESTOQUE | J35: =IF(F35=$N$2,"RECEBIMENTO",IF(F35=$N$3,"CIQ",IF(F35=$N$4,"PMM",IF(F35=$N$5,"ESTOQUE",IF(F35=$N$6,"EXPEDIÇÃO",""))))) -> ESTOQUE | K35: =IFERROR(__xludf.DUMMYFUNCTION("""COMPUTED_VALUE"""),"Jose Antoniel Silva Mesquita") -> Jose Antoniel Silva Mesquita
A36: =IFERROR(__xludf.DUMMYFUNCTION("""COMPUTED_VALUE"""),45882.0) -> 45882 | B36: =IFERROR(__xludf.DUMMYFUNCTION("""COMPUTED_VALUE"""),"MCC046UC0215") -> MCC046UC0215 | C36: =IFERROR(__xludf.DUMMYFUNCTION("""COMPUTED_VALUE"""),"CANETA ESFEROGRAFICA ECONOMIC AZUL BIC") -> CANETA ESFEROGRAFICA ECONOMIC AZUL BIC | D36: =IFERROR(__xludf.DUMMYFUNCTION("""COMPUTED_VALUE"""),5.0) -> 5 | E36: =IFERROR(__xludf.DUMMYFUNCTION("""COMPUTED_VALUE"""),"Saída") -> Saída | F36: =IFERROR(__xludf.DUMMYFUNCTION("""COMPUTED_VALUE"""),"Recebimento:truck:") -> Recebimento:truck: | G36: {=XLOOKUP(B36,'Página9'!A:A,'Página9'!F:F,"")} -> -20 | H36: {=XLOOKUP(B36,'Página9'!A:A,'Página9'!C:C,"")} -> 15 | I36: {=XLOOKUP(B36,'Página9'!A:A,'Página9'!G:G,"")} -> REPOR ESTOQUE | J36: =IF(F36=$N$2,"RECEBIMENTO",IF(F36=$N$3,"CIQ",IF(F36=$N$4,"PMM",IF(F36=$N$5,"ESTOQUE",IF(F36=$N$6,"EXPEDIÇÃO",""))))) -> RECEBIMENTO | K36: =IFERROR(__xludf.DUMMYFUNCTION("""COMPUTED_VALUE"""),"Ana Virginia De Castro Costa") -> Ana Virginia De Castro Costa
A37: =IFERROR(__xludf.DUMMYFUNCTION("""COMPUTED_VALUE"""),45882.0) -> 45882 | B37: =IFERROR(__xludf.DUMMYFUNCTION("""COMPUTED_VALUE"""),"MCC046UC0687") -> MCC046UC0687 | C37: =IFERROR(__xludf.DUMMYFUNCTION("""COMPUTED_VALUE"""),"ETIQUETA COUCHE - 100X100X 1") -> ETIQUETA COUCHE - 100X100X 1 | D37: =IFERROR(__xludf.DUMMYFUNCTION("""COMPUTED_VALUE"""),2.0) -> 2 | E37: =IFERROR(__xludf.DUMMYFUNCTION("""COMPUTED_VALUE"""),"Saída") -> Saída | F37: =IFERROR(__xludf.DUMMYFUNCTION("""COMPUTED_VALUE"""),"Estoque:package:") -> Estoque:package: | G37: {=XLOOKUP(B37,'Página9'!A:A,'Página9'!F:F,"")} -> 335 | H37: {=XLOOKUP(B37,'Página9'!A:A,'Página9'!C:C,"")} -> 20 | I37: {=XLOOKUP(B37,'Página9'!A:A,'Página9'!G:G,"")} -> OK | J37: =IF(F37=$N$2,"RECEBIMENTO",IF(F37=$N$3,"CIQ",IF(F37=$N$4,"PMM",IF(F37=$N$5,"ESTOQUE",IF(F37=$N$6,"EXPEDIÇÃO",""))))) -> ESTOQUE | K37: =IFERROR(__xludf.DUMMYFUNCTION("""COMPUTED_VALUE"""),"Paulo Henrique Chagas De Oliveira") -> Paulo Henrique Chagas De Oliveira
A38: =IFERROR(__xludf.DUMMYFUNCTION("""COMPUTED_VALUE"""),45882.0) -> 45882 | B38: =IFERROR(__xludf.DUMMYFUNCTION("""COMPUTED_VALUE"""),"MCC046UC0398") -> MCC046UC0398 | C38: =IFERROR(__xludf.DUMMYFUNCTION("""COMPUTED_VALUE"""),"GRAMPO 26/6 COBREADO CX.C/5000 BACCHI") -> GRAMPO 26/6 COBREADO CX.C/5000 BACCHI | D38: =IFERROR(__xludf.DUMMYFUNCTION("""COMPUTED_VALUE"""),1.0) -> 1 | E38: =IFERROR(__xludf.DUMMYFUNCTION("""COMPUTED_VALUE"""),"Saída") -> Saída | F38: =IFERROR(__xludf.DUMMYFUNCTION("""COMPUTED_VALUE"""),"Recebimento:truck:") -> Recebimento:truck: | G38: {=XLOOKUP(B38,'Página9'!A:A,'Página9'!F:F,"")} -> -13 | H38: {=XLOOKUP(B38,'Página9'!A:A,'Página9'!C:C,"")} -> 3 | I38: {=XLOOKUP(B38,'Página9'!A:A,'Página9'!G:G,"")} -> REPOR ESTOQUE | J38: =IF(F38=$N$2,"RECEBIMENTO",IF(F38=$N$3,"CIQ",IF(F38=$N$4,"PMM",IF(F38=$N$5,"ESTOQUE",IF(F38=$N$6,"EXPEDIÇÃO",""))))) -> RECEBIMENTO | K38: =IFERROR(__xludf.DUMMYFUNCTION("""COMPUTED_VALUE"""),"Ana Virginia De Castro Costa") -> Ana Virginia De Castro Costa
A39: =IFERROR(__xludf.DUMMYFUNCTION("""COMPUTED_VALUE"""),45882.0) -> 45882 | B39: =IFERROR(__xludf.DUMMYFUNCTION("""COMPUTED_VALUE"""),"MCC046UC0687") -> MCC046UC0687 | C39: =IFERROR(__xludf.DUMMYFUNCTION("""COMPUTED_VALUE"""),"ETIQUETA COUCHE - 100X100X 1") -> ETIQUETA COUCHE - 100X100X 1 | D39: =IFERROR(__xludf.DUMMYFUNCTION("""COMPUTED_VALUE"""),1.0) -> 1 | E39: =IFERROR(__xludf.DUMMYFUNCTION("""COMPUTED_VALUE"""),"Saída") -> Saída | F39: =IFERROR(__xludf.DUMMYFUNCTION("""COMPUTED_VALUE"""),"Recebimento:truck:") -> Recebimento:truck: | G39: {=XLOOKUP(B39,'Página9'!A:A,'Página9'!F:F,"")} -> 335 | H39: {=XLOOKUP(B39,'Página9'!A:A,'Página9'!C:C,"")} -> 20 | I39: {=XLOOKUP(B39,'Página9'!A:A,'Página9'!G:G,"")} -> OK | J39: =IF(F39=$N$2,"RECEBIMENTO",IF(F39=$N$3,"CIQ",IF(F39=$N$4,"PMM",IF(F39=$N$5,"ESTOQUE",IF(F39=$N$6,"EXPEDIÇÃO",""))))) -> RECEBIMENTO | K39: =IFERROR(__xludf.DUMMYFUNCTION("""COMPUTED_VALUE"""),"Suellen Aguiar Da Silva") -> Suellen Aguiar Da Silva
A40: =IFERROR(__xludf.DUMMYFUNCTION("""COMPUTED_VALUE"""),45882.0) -> 45882 | B40: =IFERROR(__xludf.DUMMYFUNCTION("""COMPUTED_VALUE"""),"MCC046UC0082") -> MCC046UC0082 | C40: =IFERROR(__xludf.DUMMYFUNCTION("""COMPUTED_VALUE"""),"PAPEL SULFITE A4 75G 500 FOLHAS") -> PAPEL SULFITE A4 75G 500 FOLHAS | D40: =IFERROR(__xludf.DUMMYFUNCTION("""COMPUTED_VALUE"""),2.0) -> 2 | E40: =IFERROR(__xludf.DUMMYFUNCTION("""COMPUTED_VALUE"""),"Saída") -> Saída | F40: =IFERROR(__xludf.DUMMYFUNCTION("""COMPUTED_VALUE"""),"Expedição:ex-escolas-exponenciais:") -> Expedição:ex-escolas-exponenciais: | G40: {=XLOOKUP(B40,'Página9'!A:A,'Página9'!F:F,"")} -> 163 | H40: {=XLOOKUP(B40,'Página9'!A:A,'Página9'!C:C,"")} -> 10 | I40: {=XLOOKUP(B40,'Página9'!A:A,'Página9'!G:G,"")} -> OK | J40: =IF(F40=$N$2,"RECEBIMENTO",IF(F40=$N$3,"CIQ",IF(F40=$N$4,"PMM",IF(F40=$N$5,"ESTOQUE",IF(F40=$N$6,"EXPEDIÇÃO",""))))) -> EXPEDIÇÃO | K40: =IFERROR(__xludf.DUMMYFUNCTION("""COMPUTED_VALUE"""),"Jose Antoniel Silva Mesquita") -> Jose Antoniel Silva Mesquita
...

Sheet E
A1: Data | B1: IDdoInsumo | C1: Descrição | D1: Quantidade | E1: Responsável | F1: Movimentação
A2: 45856 | B2: MCC046UC0164 | C2: APAGADOR P/ QUADRO BRANCO RADEX | D2: 2 | E2: Francisco Edson Oliveira Dos Santos Vieira | F2: =IF(A2<>"","Entrada","") -> Entrada
A3: 45856 | B3: MCC015UC0038 | C3: BOBINA SHRINK 500MM | D3: 7 | E3: Francisco Edson Oliveira Dos Santos Vieira | F3: =IF(A3<>"","Entrada","") -> Entrada
A4: 45856 | B4: MCC046UC0210 | C4: CALCULADORA MESA 12 DIGITOS ZT 712 ZETA | D4: 20 | E4: Francisco Edson Oliveira Dos Santos Vieira | F4: =IF(A4<>"","Entrada","") -> Entrada
A5: 45856 | B5: MCC049UC0601 | C5: CANETA ESFEROGRAFICA COMPACTOR VERMELHA | D5: 80 | E5: Francisco Edson Oliveira Dos Santos Vieira | F5: =IF(A5<>"","Entrada","") -> Entrada
A6: 45856 | B6: MCC046UC0215 | C6: CANETA ESFEROGRAFICA ECONOMIC AZUL BIC | D6: 118 | E6: Francisco Edson Oliveira Dos Santos Vieira | F6: =IF(A6<>"","Entrada","") -> Entrada
A7: 45856 | B7: MCC046UC0216 | C7: CANETA ESFEROGRAFICA ECONOMIC PRETA BIC | D7: 146 | E7: Francisco Edson Oliveira Dos Santos Vieira | F7: =IF(A7<>"","Entrada","") -> Entrada
A8: 45856 | B8: MCC046UC0525 | C8: CANETA PINCEL ATOMICO AZUL PILOT 1100 | D8: 25 | E8: Francisco Edson Oliveira Dos Santos Vieira | F8: =IF(A8<>"","Entrada","") -> Entrada
A9: 45856 | B9: MCC046UC0526 | C9: CANETA PINCEL ATOMICO PRETA PILOT 1100 | D9: 19 | E9: Francisco Edson Oliveira Dos Santos Vieira | F9: =IF(A9<>"","Entrada","") -> Entrada
A10: 45856 | B10: MCC046UC0674 | C10: CLIPS 6/0 | D10: 8 | E10: Francisco Edson Oliveira Dos Santos Vieira | F10: =IF(A10<>"","Entrada","") -> Entrada
A11: 45856 | B11: MCC046UC0052 | C11: CLIPS 8/0 | D11: 10 | E11: Francisco Edson Oliveira Dos Santos Vieira | F11: =IF(A11<>"","Entrada","") -> Entrada
A12: 45856 | B12: MCC046UC0617 | C12: CLIPS CHAPARRAU 2/0 CX C/100 UN GALV. | D12: 17 | E12: Francisco Edson Oliveira Dos Santos Vieira | F12: =IF(A12<>"","Entrada","") -> Entrada
A13: 45856 | B13: MCC046UC0315 | C13: ESTILETE 18MM PLASTICO LARGO BRW | D13: 0 | E13: Francisco Edson Oliveira Dos Santos Vieira | F13: =IF(A13<>"","Entrada","") -> Entrada
... A61: 45856 | B61: EMC015MO0007 | C61: RIBBON CERA PRETO 110MMX74M | D61: 177 | E61: Francisco Edson Oliveira Dos Santos Vieira | F61: =IF(A61<>"","Entrada","") -> Entrada
A62: 45856 | B62: MCC046UC0587 | C62: TESOURA USO GERAL 21CM MUNDIAL 160-8N | D62: =3 -> 3 | E62: Francisco Edson Oliveira Dos Santos Vieira | F62: =IF(A62<>"","Entrada","") -> Entrada
A63: 45931 | B63: MCC015UC0045 | C63: FITA ADESIVA 69MM X 100M | D63: 250 | E63: Francisco Edson Oliveira Dos Santos Vieira | F63: =IF(A63<>"","Entrada","") -> Entrada
A64: 45931 | B64: MCC046UC0082 | C64: PAPEL SULFITE A4 75G 500 FOLHAS | D64: 129 | E64: Francisco Edson Oliveira Dos Santos Vieira | F64: =IF(A64<>"","Entrada","") -> Entrada
A65: 45937 | B65: MCC015UC0008 | C65: FILME STRETCH 500X25 | D65: 191 | E65: Francisco Edson Oliveira Dos Santos Vieira | F65: =IF(A65<>"","Entrada","") -> Entrada
A66: 45937 | B66: MCC015UC0038 | C66: BOBINA SHRINK 500MM | D66: 11 | E66: Francisco Edson Oliveira Dos Santos Vieira | F66: =IF(A66<>"","Entrada","") -> Entrada
A67: 45954 | B67: MCC015UC0008 | C67: FILME STRETCH 500X25 | D67: 204 | E67: Francisco Edson Oliveira Dos Santos Vieira | F67: =IF(A67<>"","Entrada","") -> Entrada
A68: 45968 | B68: MCC015UC0008 | C68: FILME STRETCH 500X25 | D68: 300 | E68: Francisco Edson Oliveira Dos Santos Vieira | F68: =IF(A68<>"","Entrada","") -> Entrada
A69: 45937 | B69: MCC015UC0038 | C69: BOBINA SHRINK 500MM | D69: 20 | E69: Francisco Edson Oliveira Dos Santos Vieira | F69: =IF(A69<>"","Entrada","") -> Entrada
A70: 45976 | B70: MCC015UC0033 | C70: FITA DE ARQUEAR PET VERDE 16MM X 0,8MM C/ 13KG | D70: 15 | E70: Francisco Edson Oliveira Dos Santos Vieira | F70: =IF(A70<>"","Entrada","") -> Entrada
A71: 45973 | B71: MCC046UC0215 | C71: CANETA ESFEROGRAFICA ECONOMIC AZUL BIC | D71: 50 | E71: Francisco Edson Oliveira Dos Santos Vieira | F71: =IF(A71<>"","Entrada","") -> Entrada
A72: 45972 | B72: MCC015UC0045 | C72: FITA ADESIVA 69MM X 100M | D72: 300 | E72: Francisco Edson Oliveira Dos Santos Vieira | F72: =IF(A72<>"","Entrada","") -> Entrada
A73: 45973 | B73: MCC049UC0607 | C73: PAPEL A3 RESMA COM 500 FLS | D73: 10 | E73: Francisco Edson Oliveira Dos Santos Vieira | F73: =IF(A73<>"","Entrada","") -> Entrada
A74: 45973 | B74: MCC049UC0603 | C74: PLASTICO PLASTIF. A-4 220/307 C/100 UN PROLAM | D74: 500 | E74: Francisco Edson Oliveira Dos Santos Vieira | F74: =IF(A74<>"","Entrada","") -> Entrada
... A96: 46107 | B96: MCC046UC0599 | C96: ETIQUETA ADESIVA COUCHE AMARELA - 105X150MM SAS | D96: 32 | E96: Francisco Edson Oliveira Dos Santos Vieira | F96: =IF(A96<>"","Entrada","") -> Entrada
F97: =IF(A97<>"","Entrada","")
F98: =IF(A98<>"","Entrada","")
F99: =IF(A99<>"","Entrada","")
F100: =IF(A100<>"","Entrada","")
F101: =IF(A101<>"","Entrada","")
F102: =IF(A102<>"","Entrada","")
F103: =IF(A103<>"","Entrada","")
F104: =IF(A104<>"","Entrada","")
F106: =IF(A106<>"","Entrada","")
F107: =IF(A107<>"","Entrada","")
F108: =IF(A108<>"","Entrada","")
F109: =IF(A109<>"","Entrada","")
...

Sheet S
A1: Data | B1: Solicitante Slack | C1: Item com Código | D1: Quantidade | E1: Setor | F1: Justificativa | G1: Código | H1: Moviementação | I1: Solitado por
